Workbook

Sheet Sheet1
A1: Year | B1: Type | C1: Method | D1: Group | E1: Count | F1: ParNums | G1: Unnamed: 6 | H1: Unnamed: 7 | I1: Unnamed: 8 | J1: Unnamed: 9 | K1: Unnamed: 10 | L1: Unnamed: 11 | M1: Unnamed: 12 | N1: Unnamed: 13 | O1: Unnamed: 14 | P1: Unnamed: 15 | Q1: Unnamed: 16 | R1: Unnamed: 17 | S1: Unnamed: 18 | T1: Unnamed: 19 | U1: Unnamed: 20 | V1: Unnamed: 21 | W1: Unnamed: 22 | X1: Unnamed: 23 | Y1: Unnamed: 24 | Z1: Unnamed: 25 | AA1: Unnamed: 26 | AB1: Unnamed: 27 | AC1: Unnamed: 28 | AD1: Unnamed: 29 | AE1: Unnamed: 30 | AF1: Unnamed: 31
A2: 2011 | B2: avg | C2: Quantile70_Group | D2: High importance & High interaction | E2: 23 | F2: group 5 (GW_DELAY) | G2: group 5 (RCHRG_DP) | H2: group 7 (RCHRG_DP) | I2: group 8 (GW_REVAP) | J2: group 8 (RCHRG_DP) | K2: group 10 (GW_REVAP) | L2: group 10 (GW_DELAY) | M2: group 10 (RCHRG_DP) | N2: group 12 (GWQMN) | O2: group 12 (RCHRG_DP) | P2: group 17 (GW_DELAY) | Q2: group 13 (GW_DELAY) | R2: group 13 (GWQMN) | S2: group 13 (RCHRG_DP) | T2: group 5 (ESCO) | U2: group 10 (ESCO) | V2: group 13 (ESCO) | W2: group 2 (CN2) | X2: group 5 (CN2) | Y2: group 8 (CN2) | Z2: group 10 (CN2) | AA2: group 12 (CN2) | AB2: group 13 (CN2)
A3: 2012 | B3: avg | C3: Quantile70_Group | D3: High importance & High interaction | E3: 26 | F3: group 5 (GW_REVAP) | G3: group 5 (RCHRG_DP) | H3: group 7 (RCHRG_DP) | I3: group 8 (RCHRG_DP) | J3: group 10 (GW_REVAP) | K3: group 10 (GW_DELAY) | L3: group 10 (GWQMN) | M3: group 10 (RCHRG_DP) | N3: group 14 (GWQMN) | O3: group 12 (GWQMN) | P3: group 12 (RCHRG_DP) | Q3: group 17 (GWQMN) | R3: group 17 (RCHRG_DP) | S3: group 13 (GWQMN) | T3: group 13 (RCHRG_DP) | U3: group 2 (ESCO) | V3: group 5 (ESCO) | W3: group 10 (ESCO) | X3: group 13 (ESCO) | Y3: group 2 (CN2) | Z3: group 5 (CN2) | AA3: group 7 (CN2) | AB3: group 8 (CN2) | AC3: group 10 (CN2) | AD3: group 17 (CN2) | AE3: group 13 (CN2)
A4: 2013 | B4: avg | C4: Quantile70_Group | D4: High importance & High interaction | E4: 25 | F4: group 5 (GW_REVAP) | G4: group 5 (RCHRG_DP) | H4: group 7 (RCHRG_DP) | I4: group 8 (RCHRG_DP) | J4: group 10 (GW_REVAP) | K4: group 10 (GW_DELAY) | L4: group 10 (GWQMN) | M4: group 10 (RCHRG_DP) | N4: group 12 (GW_REVAP) | O4: group 12 (GWQMN) | P4: group 12 (RCHRG_DP) | Q4: group 17 (GWQMN) | R4: group 17 (RCHRG_DP) | S4: group 13 (GW_DELAY) | T4: group 13 (GWQMN) | U4: group 13 (RCHRG_DP) | V4: group 5 (ESCO) | W4: group 8 (ESCO) | X4: group 10 (ESCO) | Y4: group 13 (ESCO) | Z4: group 5 (CN2) | AA4: group 7 (CN2) | AB4: group 8 (CN2) | AC4: group 10 (CN2) | AD4: group 13 (CN2)
A5: 2014 | B5: avg | C5: Quantile70_Group | D5: High importance & High interaction | E5: 24 | F5: group 5 (RCHRG_DP) | G5: group 8 (RCHRG_DP) | H5: group 10 (GW_REVAP) | I5: group 10 (GW_DELAY) | J5: group 10 (RCHRG_DP) | K5: group 12 (RCHRG_DP) | L5: group 13 (GWQMN) | M5: group 13 (RCHRG_DP) | N5: group 1 (ESCO) | O5: group 2 (ESCO) | P5: group 5 (ESCO) | Q5: group 10 (ESCO) | R5: group 13 (ESCO) | S5: group 1 (CN2) | T5: group 3 (CN2) | U5: group 2 (CN2) | V5: group 4 (CN2) | W5: group 5 (CN2) | X5: group 7 (CN2) | Y5: group 8 (CN2) | Z5: group 10 (CN2) | AA5: group 12 (CN2) | AB5: group 17 (CN2) | AC5: group 13 (CN2)
A6: 2015 | B6: avg | C6: Quantile70_Group | D6: High importance & High interaction | E6: 25 | F6: group 5 (GW_REVAP) | G6: group 5 (GW_DELAY) | H6: group 5 (RCHRG_DP) | I6: group 7 (RCHRG_DP) | J6: group 8 (RCHRG_DP) | K6: group 10 (GW_REVAP) | L6: group 10 (GWQMN) | M6: group 10 (RCHRG_DP) | N6: group 12 (GW_REVAP) | O6: group 12 (GWQMN) | P6: group 12 (RCHRG_DP) | Q6: group 17 (GWQMN) | R6: group 17 (RCHRG_DP) | S6: group 13 (GW_DELAY) | T6: group 13 (GWQMN) | U6: group 13 (RCHRG_DP) | V6: group 7 (ESCO) | W6: group 8 (ESCO) | X6: group 10 (ESCO) | Y6: group 13 (ESCO) | Z6: group 5 (CN2) | AA6: group 7 (CN2) | AB6: group 8 (CN2) | AC6: group 10 (CN2) | AD6: group 13 (CN2)
A7: 2016 | B7: avg | C7: Quantile70_Group | D7: High importance & High interaction | E7: 24 | F7: group 5 (GW_REVAP) | G7: group 5 (RCHRG_DP) | H7: group 7 (RCHRG_DP) | I7: group 8 (RCHRG_DP) | J7: group 10 (GW_REVAP) | K7: group 10 (GW_DELAY) | L7: group 10 (GWQMN) | M7: group 10 (RCHRG_DP) | N7: group 12 (RCHRG_DP) | O7: group 17 (GWQMN) | P7: group 13 (GWQMN) | Q7: group 13 (RCHRG_DP) | R7: group 2 (ESCO) | S7: group 5 (ESCO) | T7: group 10 (ESCO) | U7: group 13 (ESCO) | V7: group 2 (CN2) | W7: group 5 (CN2) | X7: group 7 (CN2) | Y7: group 8 (CN2) | Z7: group 10 (CN2) | AA7: group 12 (CN2) | AB7: group 17 (CN2) | AC7: group 13 (CN2)
A8: 2017 | B8: avg | C8: Quantile70_Group | D8: High importance & High interaction | E8: 25 | F8: group 5 (GW_REVAP) | G8: group 5 (GW_DELAY) | H8: group 5 (RCHRG_DP) | I8: group 7 (RCHRG_DP) | J8: group 8 (RCHRG_DP) | K8: group 10 (GW_REVAP) | L8: group 10 (GW_DELAY) | M8: group 10 (GWQMN) | N8: group 10 (RCHRG_DP) | O8: group 12 (GW_REVAP) | P8: group 12 (GWQMN) | Q8: group 12 (RCHRG_DP) | R8: group 17 (GWQMN) | S8: group 13 (GWQMN) | T8: group 13 (RCHRG_DP) | U8: group 5 (ESCO) | V8: group 10 (ESCO) | W8: group 12 (ESCO) | X8: group 13 (ESCO) | Y8: group 2 (CN2) | Z8: group 5 (CN2) | AA8: group 8 (CN2) | AB8: group 10 (CN2) | AC8: group 17 (CN2) | AD8: group 13 (CN2)
A9: 2018 | B9: avg | C9: Quantile70_Group | D9: High importance & High interaction | E9: 26 | F9: group 5 (GW_REVAP) | G9: group 5 (RCHRG_DP) | H9: group 7 (RCHRG_DP) | I9: group 8 (RCHRG_DP) | J9: group 10 (GW_REVAP) | K9: group 10 (GW_DELAY) | L9: group 10 (GWQMN) | M9: group 10 (RCHRG_DP) | N9: group 12 (GW_REVAP) | O9: group 12 (GWQMN) | P9: group 12 (RCHRG_DP) | Q9: group 17 (GWQMN) | R9: group 13 (GW_REVAP) | S9: group 13 (GWQMN) | T9: group 13 (RCHRG_DP) | U9: group 5 (ESCO) | V9: group 8 (ESCO) | W9: group 10 (ESCO) | X9: group 12 (ESCO) | Y9: group 13 (ESCO) | Z9: group 2 (CN2) | AA9: group 5 (CN2) | AB9: group 8 (CN2) | AC9: group 10 (CN2) | AD9: group 17 (CN2) | AE9: group 13 (CN2)
A10: 2019 | B10: avg | C10: Quantile70_Group | D10: High importance & High interaction | E10: 27 | F10: group 5 (GW_REVAP) | G10: group 5 (GW_DELAY) | H10: group 5 (RCHRG_DP) | I10: group 7 (RCHRG_DP) | J10: group 8 (GW_DELAY) | K10: group 8 (RCHRG_DP) | L10: group 10 (GW_REVAP) | M10: group 10 (GW_DELAY) | N10: group 10 (GWQMN) | O10: group 10 (RCHRG_DP) | P10: group 12 (GW_REVAP) | Q10: group 12 (GWQMN) | R10: group 12 (RCHRG_DP) | S10: group 17 (GW_DELAY) | T10: group 13 (GW_REVAP) | U10: group 13 (GW_DELAY) | V10: group 13 (GWQMN) | W10: group 13 (RCHRG_DP) | X10: group 5 (ESCO) | Y10: group 8 (ESCO) | Z10: group 10 (ESCO) | AA10: group 12 (ESCO) | AB10: group 13 (ESCO) | AC10: group 2 (CN2) | AD10: group 5 (CN2) | AE10: group 8 (CN2) | AF10: group 10 (CN2)
A11: 2020 | B11: avg | C11: Quantile70_Group | D11: High importance & High interaction | E11: 25 | F11: group 5 (GW_DELAY) | G11: group 5 (RCHRG_DP) | H11: group 8 (RCHRG_DP) | I11: group 10 (GW_REVAP) | J11: group 10 (GW_DELAY) | K11: group 10 (RCHRG_DP) | L11: group 12 (RCHRG_DP) | M11: group 17 (RCHRG_DP) | N11: group 13 (GW_REVAP) | O11: group 13 (GW_DELAY) | P11: group 13 (GWQMN) | Q11: group 13 (RCHRG_DP) | R11: group 2 (ESCO) | S11: group 5 (ESCO) | T11: group 8 (ESCO) | U11: group 10 (ESCO) | V11: group 12 (ESCO) | W11: group 13 (ESCO) | X11: group 2 (CN2) | Y11: group 4 (CN2) | Z11: group 5 (CN2) | AA11: group 8 (CN2) | AB11: group 10 (CN2) | AC11: group 17 (CN2) | AD11: group 13 (CN2)
A12: 2011 | B12: avg | C12: Quantile70_Group | D12: High importance & Low interaction | E12: 8 | F12: group 8 (GW_DELAY) | G12: group 17 (RCHRG_DP) | H12: group 1 (ESCO) | I12: group 3 (ESCO) | J12: group 2 (ESCO) | K12: group 8 (ESCO) | L12: group 10 (EPCO) | M12: group 12 (ESCO)
A13: 2012 | B13: avg | C13: Quantile70_Group | D13: High importance & Low interaction | E13: 6 | F13: group 1 (ESCO) | G13: group 3 (ESCO) | H13: group 4 (ESCO) | I13: group 8 (ESCO) | J13: group 10 (EPCO) | K13: group 12 (ESCO)
A14: 2013 | B14: avg | C14: Quantile70_Group | D14: High importance & Low interaction | E14: 7 | F14: group 1 (RCHRG_DP) | G14: group 14 (RCHRG_DP) | H14: group 3 (ESCO) | I14: group 2 (ESCO) | J14: group 7 (ESCO) | K14: group 12 (ESCO) | L14: group 17 (ESCO)
A15: 2014 | B15: avg | C15: Quantile70_Group | D15: High importance & Low interaction | E15: 8 | F15: group 7 (RCHRG_DP) | G15: group 13 (GW_DELAY) | H15: group 3 (ESCO) | I15: group 4 (ESCO) | J15: group 7 (ESCO) | K15: group 8 (ESCO) | L15: group 12 (ESCO) | M15: group 17 (ESCO)
A16: 2015 | B16: avg | C16: Quantile70_Group | D16: High importance & Low interaction | E16: 7 | F16: group 10 (GW_DELAY) | G16: group 1 (ESCO) | H16: group 3 (ESCO) | I16: group 2 (ESCO) | J16: group 4 (ESCO) | K16: group 5 (ESCO) | L16: group 12 (ESCO)
A17: 2016 | B17: avg | C17: Quantile70_Group | D17: High importance & Low interaction | E17: 8 | F17: group 17 (RCHRG_DP) | G17: group 1 (ESCO) | H17: group 3 (ESCO) | I17: group 4 (ESCO) | J17: group 7 (ESCO) | K17: group 8 (ESCO) | L17: group 12 (ESCO) | M17: group 17 (ESCO)
A18: 2017 | B18: avg | C18: Quantile70_Group | D18: High importance & Low interaction | E18: 8 | F18: group 13 (GW_DELAY) | G18: group 1 (ESCO) | H18: group 3 (ESCO) | I18: group 2 (ESCO) | J18: group 4 (ESCO) | K18: group 7 (ESCO) | L18: group 8 (ESCO) | M18: group 17 (ESCO)
A19: 2018 | B19: avg | C19: Quantile70_Group | D19: High importance & Low interaction | E19: 7 | F19: group 1 (ESCO) | G19: group 3 (ESCO) | H19: group 2 (ESCO) | I19: group 4 (ESCO) | J19: group 7 (ESCO) | K19: group 17 (ESCO) | L19: group 7 (CN2)
A20: 2019 | B20: avg | C20: Quantile70_Group | D20: High importance & Low interaction | E20: 6 | F20: group 17 (RCHRG_DP) | G20: group 2 (ESCO) | H20: group 7 (ESCO) | I20: group 10 (EPCO) | J20: group 17 (ESCO) | K20: group 7 (CN2)
A21: 2020 | B21: avg | C21: Quantile70_Group | D21: High importance & Low interaction | E21: 7 | F21: group 7 (RCHRG_DP) | G21: group 8 (GW_DELAY) | H21: group 1 (ESCO) | I21: group 3 (ESCO) | J21: group 4 (ESCO) | K21: group 10 (EPCO) | L21: group 17 (ESCO)
A22: 2011 | B22: max | C22: Quantile70_Group | D22: High importance & High interaction | E22: 27 | F22: group 5 (GW_DELAY) | G22: group 5 (RCHRG_DP) | H22: group 10 (GW_REVAP) | I22: group 10 (GW_DELAY) | J22: group 10 (RCHRG_DP) | K22: group 13 (GW_DELAY) | L22: group 13 (GWQMN) | M22: group 13 (RCHRG_DP) | N22: group 2 (ESCO) | O22: group 5 (ESCO) | P22: group 7 (ESCO) | Q22: group 8 (ESCO) | R22: group 10 (ESCO) | S22: group 10 (EPCO) | T22: group 12 (ESCO) | U22: group 17 (ESCO) | V22: group 13 (ESCO) | W22: group 13 (EPCO) | X22: group 2 (CN2) | Y22: group 5 (CN2) | Z22: group 7 (CN2) | AA22: group 8 (CN2) | AB22: group 10 (CN2) | AC22: group 14 (CN2) | AD22: group 12 (CN2) | AE22: group 17 (CN2) | AF22: group 13 (CN2)
A23: 2012 | B23: max | C23: Quantile70_Group | D23: High importance & High interaction | E23: 22 | F23: group 5 (RCHRG_DP) | G23: group 10 (GW_REVAP) | H23: group 10 (GW_DELAY) | I23: group 10 (GWQMN) | J23: group 10 (RCHRG_DP) | K23: group 13 (GWQMN) | L23: group 13 (RCHRG_DP) | M23: group 2 (ESCO) | N23: group 5 (ESCO) | O23: group 8 (ESCO) | P23: group 10 (ESCO) | Q23: group 10 (EPCO) | R23: group 13 (ESCO) | S23: group 1 (CN2) | T23: group 5 (CN2) | U23: group 7 (CN2) | V23: group 8 (CN2) | W23: group 10 (CN2) | X23: group 14 (CN2) | Y23: group 12 (CN2) | Z23: group 17 (CN2) | AA23: group 13 (CN2)
A24: 2013 | B24: max | C24: Quantile70_Group | D24: High importance & High interaction | E24: 25 | F24: group 5 (GW_REVAP) | G24: group 5 (GW_DELAY) | H24: group 5 (RCHRG_DP) | I24: group 8 (RCHRG_DP) | J24: group 10 (GW_REVAP) | K24: group 10 (GW_DELAY) | L24: group 10 (GWQMN) | M24: group 10 (RCHRG_DP) | N24: group 12 (GW_REVAP) | O24: group 12 (GWQMN) | P24: group 12 (RCHRG_DP) | Q24: group 17 (GWQMN) | R24: group 13 (GWQMN) | S24: group 13 (RCHRG_DP) | T24: group 3 (ESCO) | U24: group 5 (ESCO) | V24: group 10 (ESCO) | W24: group 13 (ESCO) | X24: group 3 (CN2) | Y24: group 2 (CN2) | Z24: group 4 (CN2) | AA24: group 8 (CN2) | AB24: group 10 (CN2) | AC24: group 12 (CN2) | AD24: group 13 (CN2)
A25: 2014 | B25: max | C25: Quantile70_Group | D25: High importance & High interaction | E25: 27 | F25: group 5 (GW_DELAY) | G25: group 5 (RCHRG_DP) | H25: group 10 (GW_DELAY) | I25: group 10 (RCHRG_DP) | J25: group 13 (GWQMN) | K25: group 13 (RCHRG_DP) | L25: group 7 (ESCO) | M25: group 8 (ESCO) | N25: group 8 (EPCO) | O25: group 10 (ESCO) | P25: group 10 (EPCO) | Q25: group 14 (ESCO) | R25: group 12 (ESCO) | S25: group 17 (ESCO) | T25: group 13 (ESCO) | U25: group 1 (CN2) | V25: group 3 (CN2) | W25: group 2 (CN2) | X25: group 4 (CN2) | Y25: group 5 (CN2) | Z25: group 7 (CN2) | AA25: group 8 (CN2) | AB25: group 10 (CN2) | AC25: group 14 (CN2) | AD25: group 12 (CN2) | AE25: group 17 (CN2) | AF25: group 13 (CN2)
A26: 2015 | B26: max | C26: Quantile70_Group | D26: High importance & High interaction | E26: 25 | F26: group 5 (GW_REVAP) | G26: group 5 (GW_DELAY) | H26: group 5 (RCHRG_DP) | I26: group 7 (RCHRG_DP) | J26: group 10 (GW_REVAP) | K26: group 10 (GW_DELAY) | L26: group 10 (GWQMN) | M26: group 10 (RCHRG_DP) | N26: group 12 (RCHRG_DP) | O26: group 17 (GWQMN) | P26: group 13 (GW_DELAY) | Q26: group 13 (GWQMN) | R26: group 13 (RCHRG_DP) | S26: group 7 (ESCO) | T26: group 8 (ESCO) | U26: group 10 (ESCO) | V26: group 13 (ESCO) | W26: group 5 (CN2) | X26: group 7 (CN2) | Y26: group 8 (CN2) | Z26: group 10 (CN2) | AA26: group 14 (CN2) | AB26: group 12 (CN2) | AC26: group 17 (CN2) | AD26: group 13 (CN2)
A27: 2016 | B27: max | C27: Quantile70_Group | D27: High importance & High interaction | E27: 23 | F27: group 5 (RCHRG_DP) | G27: group 10 (GW_REVAP) | H27: group 10 (GW_DELAY) | I27: group 10 (RCHRG_DP) | J27: group 13 (RCHRG_DP) | K27: group 2 (ESCO) | L27: group 5 (ESCO) | M27: group 7 (ESCO) | N27: group 8 (ESCO) | O27: group 10 (ESCO) | P27: group 17 (ESCO) | Q27: group 13 (ESCO) | R27: group 1 (CN2) | S27: group 3 (CN2) | T27: group 2 (CN2) | U27: group 5 (CN2) | V27: group 7 (CN2) | W27: group 8 (CN2) | X27: group 10 (CN2) | Y27: group 14 (CN2) | Z27: group 12 (CN2) | AA27: group 17 (CN2) | AB27: group 13 (CN2)
A28: 2017 | B28: max | C28: Quantile70_Group | D28: High importance & High interaction | E28: 23 | F28: group 5 (GW_REVAP) | G28: group 5 (RCHRG_DP) | H28: group 10 (GW_REVAP) | I28: group 10 (GW_DELAY) | J28: group 10 (GWQMN) | K28: group 10 (RCHRG_DP) | L28: group 17 (GWQMN) | M28: group 13 (GWQMN) | N28: group 13 (RCHRG_DP) | O28: group 10 (ESCO) | P28: group 12 (ESCO) | Q28: group 13 (ESCO) | R28: group 1 (CN2) | S28: group 3 (CN2) | T28: group 2 (CN2) | U28: group 5 (CN2) | V28: group 7 (CN2) | W28: group 8 (CN2) | X28: group 10 (CN2) | Y28: group 14 (CN2) | Z28: group 12 (CN2) | AA28: group 17 (CN2) | AB28: group 13 (CN2)
A29: 2018 | B29: max | C29: Quantile70_Group | D29: High importance & High interaction | E29: 24 | F29: group 5 (GW_REVAP) | G29: group 5 (RCHRG_DP) | H29: group 10 (GW_DELAY) | I29: group 10 (GWQMN) | J29: group 10 (RCHRG_DP) | K29: group 12 (GW_REVAP) | L29: group 12 (GWQMN) | M29: group 17 (GWQMN) | N29: group 13 (GWQMN) | O29: group 13 (RCHRG_DP) | P29: group 8 (ESCO) | Q29: group 10 (ESCO) | R29: group 10 (EPCO) | S29: group 12 (ESCO) | T29: group 13 (ESCO) | U29: group 2 (CN2) | V29: group 5 (CN2) | W29: group 7 (CN2) | X29: group 8 (CN2) | Y29: group 10 (CN2) | Z29: group 14 (CN2) | AA29: group 12 (CN2) | AB29: group 17 (CN2) | AC29: group 13 (CN2)
A30: 2019 | B30: max | C30: Quantile70_Group | D30: High importance & High interaction | E30: 26 | F30: group 5 (GW_REVAP) | G30: group 5 (RCHRG_DP) | H30: group 10 (GW_REVAP) | I30: group 10 (GW_DELAY) | J30: group 10 (RCHRG_DP) | K30: group 13 (GW_REVAP) | L30: group 13 (GWQMN) | M30: group 13 (RCHRG_DP) | N30: group 2 (ESCO) | O30: group 8 (ESCO) | P30: group 10 (ESCO) | Q30: group 10 (EPCO) | R30: group 12 (ESCO) | S30: group 17 (ESCO) | T30: group 13 (ESCO) | U30: group 13 (EPCO) | V30: group 2 (CN2) | W30: group 4 (CN2) | X30: group 5 (CN2) | Y30: group 7 (CN2) | Z30: group 8 (CN2) | AA30: group 10 (CN2) | AB30: group 14 (CN2) | AC30: group 12 (CN2) | AD30: group 17 (CN2) | AE30: group 13 (CN2)
A31: 2020 | B31: max | C31: Quantile70_Group | D31: High importance & High interaction | E31: 25 | F31: group 5 (GW_DELAY) | G31: group 5 (RCHRG_DP) | H31: group 10 (GW_REVAP) | I31: group 10 (RCHRG_DP) | J31: group 13 (RCHRG_DP) | K31: group 2 (ESCO) | L31: group 5 (ESCO) | M31: group 7 (ESCO) | N31: group 8 (ESCO) | O31: group 10 (ESCO) | P31: group 10 (EPCO) | Q31: group 12 (ESCO) | R31: group 17 (ESCO) | S31: group 17 (EPCO) | T31: group 13 (ESCO) | U31: group 13 (EPCO) | V31: group 2 (CN2) | W31: group 5 (CN2) | X31: group 7 (CN2) | Y31: group 8 (CN2) | Z31: group 10 (CN2) | AA31: group 14 (CN2) | AB31: group 12 (CN2) | AC31: group 17 (CN2) | AD31: group 13 (CN2)
A32: 2011 | B32: max | C32: Quantile70_Group | D32: High importance & Low interaction | E32: 4 | F32: group 1 (ESCO) | G32: group 3 (ESCO) | H32: group 4 (ESCO) | I32: group 14 (ESCO)
A33: 2012 | B33: max | C33: Quantile70_Group | D33: High importance & Low interaction | E33: 7 | F33: group 5 (GW_DELAY) | G33: group 1 (ESCO) | H33: group 12 (ESCO) | I33: group 17 (ESCO) | J33: group 3 (CN2) | K33: group 2 (CN2) | L33: group 4 (CN2)
A34: 2013 | B34: max | C34: Quantile70_Group | D34: High importance & Low interaction | E34: 5 | F34: group 13 (GW_DELAY) | G34: group 2 (ESCO) | H34: group 8 (ESCO) | I34: group 12 (ESCO) | J34: group 7 (CN2)
A35: 2014 | B35: max | C35: Quantile70_Group | D35: High importance & Low interaction | E35: 2 | F35: group 13 (GW_DELAY) | G35: group 5 (ESCO)
A36: 2015 | B36: max | C36: Quantile70_Group | D36: High importance & Low interaction | E36: 4 | F36: group 8 (RCHRG_DP) | G36: group 17 (RCHRG_DP) | H36: group 5 (ESCO) | I36: group 12 (ESCO)
A37: 2016 | B37: max | C37: Quantile70_Group | D37: High importance & Low interaction | E37: 5 | F37: group 1 (ESCO) | G37: group 3 (ESCO) | H37: group 4 (ESCO) | I37: group 12 (ESCO) | J37: group 4 (CN2)
A38: 2017 | B38: max | C38: Quantile70_Group | D38: High importance & Low interaction | E38: 6 | F38: group 8 (RCHRG_DP) | G38: group 12 (RCHRG_DP) | H38: group 13 (GW_DELAY) | I38: group 5 (ESCO) | J38: group 8 (ESCO) | K38: group 4 (CN2)
A39: 2018 | B39: max | C39: Quantile70_Group | D39: High importance & Low interaction | E39: 4 | F39: group 12 (RCHRG_DP) | G39: group 1 (ESCO) | H39: group 2 (ESCO) | I39: group 5 (ESCO)
A40: 2019 | B40: max | C40: Quantile70_Group | D40: High importance & Low interaction | E40: 5 | F40: group 12 (RCHRG_DP) | G40: group 13 (GW_DELAY) | H40: group 1 (ESCO) | I40: group 3 (ESCO) | J40: group 5 (ESCO)
...

Sheet Sheet7
A3: Count of GroupNum | B3: Column Labels | P3: 1 | Q3: 3
A4: Row Labels | B4: 1 | C4: 10 | D4: 12 | E4: 13 | F4: 14 | G4: 17 | H4: 2 | I4: 3 | J4: 4 | K4: 5 | L4: 7 | M4: 8 | N4: Grand Total | P4: 2 | Q4: 7
A5: CN2 | B5: 1 | C5: 1 | D5: 1 | E5: 1 | F5: 1 | G5: 1 | H5: 1 | I5: 1 | J5: 1 | K5: 1 | L5: 1 | M5: 1 | N5: 12 | P5: 3 | Q5: 5
A6: EPCO | C6: 1 | E6: 1 | G6: 1 | K6: 1 | M6: 1 | N6: 5 | P6: 4 | Q6: 5
A7: ESCO | B7: 1 | C7: 1 | D7: 1 | E7: 1 | F7: 1 | G7: 1 | H7: 1 | I7: 1 | J7: 1 | K7: 1 | L7: 1 | M7: 1 | N7: 12 | P7: 5 | Q7: 13
A8: GW_DELAY | C8: 1 | D8: 1 | E8: 1 | F8: 1 | G8: 1 | K8: 1 | M8: 1 | N8: 7 | P8: 7 | Q8: 3
A9: GW_REVAP | C9: 1 | D9: 1 | E9: 1 | K9: 1 | M9: 1 | N9: 5 | P9: 8 | Q9: 9
A10: GWQMN | C10: 1 | D10: 1 | E10: 1 | F10: 1 | G10: 1 | N10: 5 | P10: 10 | Q10: 19
A11: RCHRG_DP | B11: 1 | C11: 1 | D11: 1 | E11: 1 | F11: 1 | G11: 1 | K11: 1 | L11: 1 | M11: 1 | N11: 9 | P11: 12 | Q11: 3
A12: Grand Total | B12: 3 | C12: 7 | D12: 6 | E12: 7 | F12: 5 | G12: 6 | H12: 2 | I12: 2 | J12: 2 | K12: 6 | L12: 3 | M12: 6 | N12: 55 | P12: 13 | Q12: 19
P13: 14 | Q13: 1
P14: 17 | Q14: 1

Sheet Table1
A1: Attribute | B1: Value | C1: Custom | D1: GroupNum
A2: Column1 | B2: group 5 (GW_DELAY) | C2: GW_DELAY | D2: 5
A3: Column2 | B3: group 5 (RCHRG_DP) | C3: RCHRG_DP | D3: 5
A4: Column3 | B4: group 7 (RCHRG_DP) | C4: RCHRG_DP | D4: 7
A5: Column4 | B5: group 8 (GW_REVAP) | C5: GW_REVAP | D5: 8
A6: Column5 | B6: group 8 (RCHRG_DP) | C6: RCHRG_DP | D6: 8
A7: Column6 | B7: group 10 (GW_REVAP) | C7: GW_REVAP | D7: 10
A8: Column7 | B8: group 10 (GW_DELAY) | C8: GW_DELAY | D8: 10
A9: Column8 | B9: group 10 (RCHRG_DP) | C9: RCHRG_DP | D9: 10
A10: Column9 | B10: group 12 (GWQMN) | C10: GWQMN | D10: 12
A11: Column10 | B11: group 12 (RCHRG_DP) | C11: RCHRG_DP | D11: 12
A12: Column11 | B12: group 17 (GW_DELAY) | C12: GW_DELAY | D12: 17
... A56: Column3 | B56: group 5 (EPCO) | C56: EPCO | D56: 5

Sheet pivot for group counts
A1: Column1 | B1: Column2 | C1: Column3 | D1: Column4 | E1: Column5 | F1: Column6 | G1: Column7 | H1: Column8 | I1: Column9 | J1: Column10 | K1: Column11 | L1: Column12 | M1: Column13 | N1: Column14 | O1: Column15 | P1: Column16 | Q1: Column17 | R1: Column18 | S1: Column19 | T1: Column20 | U1: Column21 | V1: Column22 | W1: Column23 | X1: Column24 | Y1: Column25 | Z1: Column26 | AA1: Column27
A2: group 5 (GW_DELAY) | B2: group 5 (RCHRG_DP) | C2: group 7 (RCHRG_DP) | D2: group 8 (GW_REVAP) | E2: group 8 (RCHRG_DP) | F2: group 10 (GW_REVAP) | G2: group 10 (GW_DELAY) | H2: group 10 (RCHRG_DP) | I2: group 12 (GWQMN) | J2: group 12 (RCHRG_DP) | K2: group 17 (GW_DELAY) | L2: group 13 (GW_DELAY) | M2: group 13 (GWQMN) | N2: group 13 (RCHRG_DP) | O2: group 5 (ESCO) | P2: group 10 (ESCO) | Q2: group 13 (ESCO) | R2: group 2 (CN2) | S2: group 5 (CN2) | T2: group 8 (CN2) | U2: group 10 (CN2) | V2: group 12 (CN2) | W2: group 13 (CN2)
A3: group 5 (GW_REVAP) | B3: group 5 (RCHRG_DP) | C3: group 7 (RCHRG_DP) | D3: group 8 (RCHRG_DP) | E3: group 10 (GW_REVAP) | F3: group 10 (GW_DELAY) | G3: group 10 (GWQMN) | H3: group 10 (RCHRG_DP) | I3: group 14 (GWQMN) | J3: group 12 (GWQMN) | K3: group 12 (RCHRG_DP) | L3: group 17 (GWQMN) | M3: group 17 (RCHRG_DP) | N3: group 13 (GWQMN) | O3: group 13 (RCHRG_DP) | P3: group 2 (ESCO) | Q3: group 5 (ESCO) | R3: group 10 (ESCO) | S3: group 13 (ESCO) | T3: group 2 (CN2) | U3: group 5 (CN2) | V3: group 7 (CN2) | W3: group 8 (CN2) | X3: group 10 (CN2) | Y3: group 17 (CN2) | Z3: group 13 (CN2)
A4: group 5 (GW_REVAP) | B4: group 5 (RCHRG_DP) | C4: group 7 (RCHRG_DP) | D4: group 8 (RCHRG_DP) | E4: group 10 (GW_REVAP) | F4: group 10 (GW_DELAY) | G4: group 10 (GWQMN) | H4: group 10 (RCHRG_DP) | I4: group 12 (GW_REVAP) | J4: group 12 (GWQMN) | K4: group 12 (RCHRG_DP) | L4: group 17 (GWQMN) | M4: group 17 (RCHRG_DP) | N4: group 13 (GW_DELAY) | O4: group 13 (GWQMN) | P4: group 13 (RCHRG_DP) | Q4: group 5 (ESCO) | R4: group 8 (ESCO) | S4: group 10 (ESCO) | T4: group 13 (ESCO) | U4: group 5 (CN2) | V4: group 7 (CN2) | W4: group 8 (CN2) | X4: group 10 (CN2) | Y4: group 13 (CN2)
A5: group 5 (RCHRG_DP) | B5: group 8 (RCHRG_DP) | C5: group 10 (GW_REVAP) | D5: group 10 (GW_DELAY) | E5: group 10 (RCHRG_DP) | F5: group 12 (RCHRG_DP) | G5: group 13 (GWQMN) | H5: group 13 (RCHRG_DP) | I5: group 1 (ESCO) | J5: group 2 (ESCO) | K5: group 5 (ESCO) | L5: group 10 (ESCO) | M5: group 13 (ESCO) | N5: group 1 (CN2) | O5: group 3 (CN2) | P5: group 2 (CN2) | Q5: group 4 (CN2) | R5: group 5 (CN2) | S5: group 7 (CN2) | T5: group 8 (CN2) | U5: group 10 (CN2) | V5: group 12 (CN2) | W5: group 17 (CN2) | X5: group 13 (CN2)
A6: group 5 (GW_REVAP) | B6: group 5 (GW_DELAY) | C6: group 5 (RCHRG_DP) | D6: group 7 (RCHRG_DP) | E6: group 8 (RCHRG_DP) | F6: group 10 (GW_REVAP) | G6: group 10 (GWQMN) | H6: group 10 (RCHRG_DP) | I6: group 12 (GW_REVAP) | J6: group 12 (GWQMN) | K6: group 12 (RCHRG_DP) | L6: group 17 (GWQMN) | M6: group 17 (RCHRG_DP) | N6: group 13 (GW_DELAY) | O6: group 13 (GWQMN) | P6: group 13 (RCHRG_DP) | Q6: group 7 (ESCO) | R6: group 8 (ESCO) | S6: group 10 (ESCO) | T6: group 13 (ESCO) | U6: group 5 (CN2) | V6: group 7 (CN2) | W6: group 8 (CN2) | X6: group 10 (CN2) | Y6: group 13 (CN2)
A7: group 5 (GW_REVAP) | B7: group 5 (RCHRG_DP) | C7: group 7 (RCHRG_DP) | D7: group 8 (RCHRG_DP) | E7: group 10 (GW_REVAP) | F7: group 10 (GW_DELAY) | G7: group 10 (GWQMN) | H7: group 10 (RCHRG_DP) | I7: group 12 (RCHRG_DP) | J7: group 17 (GWQMN) | K7: group 13 (GWQMN) | L7: group 13 (RCHRG_DP) | M7: group 2 (ESCO) | N7: group 5 (ESCO) | O7: group 10 (ESCO) | P7: group 13 (ESCO) | Q7: group 2 (CN2) | R7: group 5 (CN2) | S7: group 7 (CN2) | T7: group 8 (CN2) | U7: group 10 (CN2) | V7: group 12 (CN2) | W7: group 17 (CN2) | X7: group 13 (CN2)
A8: group 5 (GW_REVAP) | B8: group 5 (GW_DELAY) | C8: group 5 (RCHRG_DP) | D8: group 7 (RCHRG_DP) | E8: group 8 (RCHRG_DP) | F8: group 10 (GW_REVAP) | G8: group 10 (GW_DELAY) | H8: group 10 (GWQMN) | I8: group 10 (RCHRG_DP) | J8: group 12 (GW_REVAP) | K8: group 12 (GWQMN) | L8: group 12 (RCHRG_DP) | M8: group 17 (GWQMN) | N8: group 13 (GWQMN) | O8: group 13 (RCHRG_DP) | P8: group 5 (ESCO) | Q8: group 10 (ESCO) | R8: group 12 (ESCO) | S8: group 13 (ESCO) | T8: group 2 (CN2) | U8: group 5 (CN2) | V8: group 8 (CN2) | W8: group 10 (CN2) | X8: group 17 (CN2) | Y8: group 13 (CN2)
A9: group 5 (GW_REVAP) | B9: group 5 (RCHRG_DP) | C9: group 7 (RCHRG_DP) | D9: group 8 (RCHRG_DP) | E9: group 10 (GW_REVAP) | F9: group 10 (GW_DELAY) | G9: group 10 (GWQMN) | H9: group 10 (RCHRG_DP) | I9: group 12 (GW_REVAP) | J9: group 12 (GWQMN) | K9: group 12 (RCHRG_DP) | L9: group 17 (GWQMN) | M9: group 13 (GW_REVAP) | N9: group 13 (GWQMN) | O9: group 13 (RCHRG_DP) | P9: group 5 (ESCO) | Q9: group 8 (ESCO) | R9: group 10 (ESCO) | S9: group 12 (ESCO) | T9: group 13 (ESCO) | U9: group 2 (CN2) | V9: group 5 (CN2) | W9: group 8 (CN2) | X9: group 10 (CN2) | Y9: group 17 (CN2) | Z9: group 13 (CN2)
A10: group 5 (GW_REVAP) | B10: group 5 (GW_DELAY) | C10: group 5 (RCHRG_DP) | D10: group 7 (RCHRG_DP) | E10: group 8 (GW_DELAY) | F10: group 8 (RCHRG_DP) | G10: group 10 (GW_REVAP) | H10: group 10 (GW_DELAY) | I10: group 10 (GWQMN) | J10: group 10 (RCHRG_DP) | K10: group 12 (GW_REVAP) | L10: group 12 (GWQMN) | M10: group 12 (RCHRG_DP) | N10: group 17 (GW_DELAY) | O10: group 13 (GW_REVAP) | P10: group 13 (GW_DELAY) | Q10: group 13 (GWQMN) | R10: group 13 (RCHRG_DP) | S10: group 5 (ESCO) | T10: group 8 (ESCO) | U10: group 10 (ESCO) | V10: group 12 (ESCO) | W10: group 13 (ESCO) | X10: group 2 (CN2) | Y10: group 5 (CN2) | Z10: group 8 (CN2) | AA10: group 10 (CN2)
A11: group 5 (GW_DELAY) | B11: group 5 (RCHRG_DP) | C11: group 8 (RCHRG_DP) | D11: group 10 (GW_REVAP) | E11: group 10 (GW_DELAY) | F11: group 10 (RCHRG_DP) | G11: group 12 (RCHRG_DP) | H11: group 17 (RCHRG_DP) | I11: group 13 (GW_REVAP) | J11: group 13 (GW_DELAY) | K11: group 13 (GWQMN) | L11: group 13 (RCHRG_DP) | M11: group 2 (ESCO) | N11: group 5 (ESCO) | O11: group 8 (ESCO) | P11: group 10 (ESCO) | Q11: group 12 (ESCO) | R11: group 13 (ESCO) | S11: group 2 (CN2) | T11: group 4 (CN2) | U11: group 5 (CN2) | V11: group 8 (CN2) | W11: group 10 (CN2) | X11: group 17 (CN2) | Y11: group 13 (CN2)
A12: group 8 (GW_DELAY) | B12: group 17 (RCHRG_DP) | C12: group 1 (ESCO) | D12: group 3 (ESCO) | E12: group 2 (ESCO) | F12: group 8 (ESCO) | G12: group 10 (EPCO) | H12: group 12 (ESCO)
A13: group 1 (ESCO) | B13: group 3 (ESCO) | C13: group 4 (ESCO) | D13: group 8 (ESCO) | E13: group 10 (EPCO) | F13: group 12 (ESCO)
A14: group 1 (RCHRG_DP) | B14: group 14 (RCHRG_DP) | C14: group 3 (ESCO) | D14: group 2 (ESCO) | E14: group 7 (ESCO) | F14: group 12 (ESCO) | G14: group 17 (ESCO)
A15: group 7 (RCHRG_DP) | B15: group 13 (GW_DELAY) | C15: group 3 (ESCO) | D15: group 4 (ESCO) | E15: group 7 (ESCO) | F15: group 8 (ESCO) | G15: group 12 (ESCO) | H15: group 17 (ESCO)
A16: group 10 (GW_DELAY) | B16: group 1 (ESCO) | C16: group 3 (ESCO) | D16: group 2 (ESCO) | E16: group 4 (ESCO) | F16: group 5 (ESCO) | G16: group 12 (ESCO)
A17: group 17 (RCHRG_DP) | B17: group 1 (ESCO) | C17: group 3 (ESCO) | D17: group 4 (ESCO) | E17: group 7 (ESCO) | F17: group 8 (ESCO) | G17: group 12 (ESCO) | H17: group 17 (ESCO)
A18: group 13 (GW_DELAY) | B18: group 1 (ESCO) | C18: group 3 (ESCO) | D18: group 2 (ESCO) | E18: group 4 (ESCO) | F18: group 7 (ESCO) | G18: group 8 (ESCO) | H18: group 17 (ESCO)
A19: group 1 (ESCO) | B19: group 3 (ESCO) | C19: group 2 (ESCO) | D19: group 4 (ESCO) | E19: group 7 (ESCO) | F19: group 17 (ESCO) | G19: group 7 (CN2)
A20: group 17 (RCHRG_DP) | B20: group 2 (ESCO) | C20: group 7 (ESCO) | D20: group 10 (EPCO) | E20: group 17 (ESCO) | F20: group 7 (CN2)
A21: group 7 (RCHRG_DP) | B21: group 8 (GW_DELAY) | C21: group 1 (ESCO) | D21: group 3 (ESCO) | E21: group 4 (ESCO) | F21: group 10 (EPCO) | G21: group 17 (ESCO)
A22: group 5 (GW_DELAY) | B22: group 5 (RCHRG_DP) | C22: group 10 (GW_REVAP) | D22: group 10 (GW_DELAY) | E22: group 10 (RCHRG_DP) | F22: group 13 (GW_DELAY) | G22: group 13 (GWQMN) | H22: group 13 (RCHRG_DP) | I22: group 2 (ESCO) | J22: group 5 (ESCO) | K22: group 7 (ESCO) | L22: group 8 (ESCO) | M22: group 10 (ESCO) | N22: group 10 (EPCO) | O22: group 12 (ESCO) | P22: group 17 (ESCO) | Q22: group 13 (ESCO) | R22: group 13 (EPCO) | S22: group 2 (CN2) | T22: group 5 (CN2) | U22: group 7 (CN2) | V22: group 8 (CN2) | W22: group 10 (CN2) | X22: group 14 (CN2) | Y22: group 12 (CN2) | Z22: group 17 (CN2) | AA22: group 13 (CN2)
A23: group 5 (RCHRG_DP) | B23: group 10 (GW_REVAP) | C23: group 10 (GW_DELAY) | D23: group 10 (GWQMN) | E23: group 10 (RCHRG_DP) | F23: group 13 (GWQMN) | G23: group 13 (RCHRG_DP) | H23: group 2 (ESCO) | I23: group 5 (ESCO) | J23: group 8 (ESCO) | K23: group 10 (ESCO) | L23: group 10 (EPCO) | M23: group 13 (ESCO) | N23: group 1 (CN2) | O23: group 5 (CN2) | P23: group 7 (CN2) | Q23: group 8 (CN2) | R23: group 10 (CN2) | S23: group 14 (CN2) | T23: group 12 (CN2) | U23: group 17 (CN2) | V23: group 13 (CN2)
A24: group 5 (GW_REVAP) | B24: group 5 (GW_DELAY) | C24: group 5 (RCHRG_DP) | D24: group 8 (RCHRG_DP) | E24: group 10 (GW_REVAP) | F24: group 10 (GW_DELAY) | G24: group 10 (GWQMN) | H24: group 10 (RCHRG_DP) | I24: group 12 (GW_REVAP) | J24: group 12 (GWQMN) | K24: group 12 (RCHRG_DP) | L24: group 17 (GWQMN) | M24: group 13 (GWQMN) | N24: group 13 (RCHRG_DP) | O24: group 3 (ESCO) | P24: group 5 (ESCO) | Q24: group 10 (ESCO) | R24: group 13 (ESCO) | S24: group 3 (CN2) | T24: group 2 (CN2) | U24: group 4 (CN2) | V24: group 8 (CN2) | W24: group 10 (CN2) | X24: group 12 (CN2) | Y24: group 13 (CN2)
A25: group 5 (GW_DELAY) | B25: group 5 (RCHRG_DP) | C25: group 10 (GW_DELAY) | D25: group 10 (RCHRG_DP) | E25: group 13 (GWQMN) | F25: group 13 (RCHRG_DP) | G25: group 7 (ESCO) | H25: group 8 (ESCO) | I25: group 8 (EPCO) | J25: group 10 (ESCO) | K25: group 10 (EPCO) | L25: group 14 (ESCO) | M25: group 12 (ESCO) | N25: group 17 (ESCO) | O25: group 13 (ESCO) | P25: group 1 (CN2) | Q25: group 3 (CN2) | R25: group 2 (CN2) | S25: group 4 (CN2) | T25: group 5 (CN2) | U25: group 7 (CN2) | V25: group 8 (CN2) | W25: group 10 (CN2) | X25: group 14 (CN2) | Y25: group 12 (CN2) | Z25: group 17 (CN2) | AA25: group 13 (CN2)
A26: group 5 (GW_REVAP) | B26: group 5 (GW_DELAY) | C26: group 5 (RCHRG_DP) | D26: group 7 (RCHRG_DP) | E26: group 10 (GW_REVAP) | F26: group 10 (GW_DELAY) | G26: group 10 (GWQMN) | H26: group 10 (RCHRG_DP) | I26: group 12 (RCHRG_DP) | J26: group 17 (GWQMN) | K26: group 13 (GW_DELAY) | L26: group 13 (GWQMN) | M26: group 13 (RCHRG_DP) | N26: group 7 (ESCO) | O26: group 8 (ESCO) | P26: group 10 (ESCO) | Q26: group 13 (ESCO) | R26: group 5 (CN2) | S26: group 7 (CN2) | T26: group 8 (CN2) | U26: group 10 (CN2) | V26: group 14 (CN2) | W26: group 12 (CN2) | X26: group 17 (CN2) | Y26: group 13 (CN2)
A27: group 5 (RCHRG_DP) | B27: group 10 (GW_REVAP) | C27: group 10 (GW_DELAY) | D27: group 10 (RCHRG_DP) | E27: group 13 (RCHRG_DP) | F27: group 2 (ESCO) | G27: group 5 (ESCO) | H27: group 7 (ESCO) | I27: group 8 (ESCO) | J27: group 10 (ESCO) | K27: group 17 (ESCO) | L27: group 13 (ESCO) | M27: group 1 (CN2) | N27: group 3 (CN2) | O27: group 2 (CN2) | P27: group 5 (CN2) | Q27: group 7 (CN2) | R27: group 8 (CN2) | S27: group 10 (CN2) | T27: group 14 (CN2) | U27: group 12 (CN2) | V27: group 17 (CN2) | W27: group 13 (CN2)
A28: group 5 (GW_REVAP) | B28: group 5 (RCHRG_DP) | C28: group 10 (GW_REVAP) | D28: group 10 (GW_DELAY) | E28: group 10 (GWQMN) | F28: group 10 (RCHRG_DP) | G28: group 17 (GWQMN) | H28: group 13 (GWQMN) | I28: group 13 (RCHRG_DP) | J28: group 10 (ESCO) | K28: group 12 (ESCO) | L28: group 13 (ESCO) | M28: group 1 (CN2) | N28: group 3 (CN2) | O28: group 2 (CN2) | P28: group 5 (CN2) | Q28: group 7 (CN2) | R28: group 8 (CN2) | S28: group 10 (CN2) | T28: group 14 (CN2) | U28: group 12 (CN2) | V28: group 17 (CN2) | W28: group 13 (CN2)
A29: group 5 (GW_REVAP) | B29: group 5 (RCHRG_DP) | C29: group 10 (GW_DELAY) | D29: group 10 (GWQMN) | E29: group 10 (RCHRG_DP) | F29: group 12 (GW_REVAP) | G29: group 12 (GWQMN) | H29: group 17 (GWQMN) | I29: group 13 (GWQMN) | J29: group 13 (RCHRG_DP) | K29: group 8 (ESCO) | L29: group 10 (ESCO) | M29: group 10 (EPCO) | N29: group 12 (ESCO) | O29: group 13 (ESCO) | P29: group 2 (CN2) | Q29: group 5 (CN2) | R29: group 7 (CN2) | S29: group 8 (CN2) | T29: group 10 (CN2) | U29: group 14 (CN2) | V29: group 12 (CN2) | W29: group 17 (CN2) | X29: group 13 (CN2)
A30: group 5 (GW_REVAP) | B30: group 5 (RCHRG_DP) | C30: group 10 (GW_REVAP) | D30: group 10 (GW_DELAY) | E30: group 10 (RCHRG_DP) | F30: group 13 (GW_REVAP) | G30: group 13 (GWQMN) | H30: group 13 (RCHRG_DP) | I30: group 2 (ESCO) | J30: group 8 (ESCO) | K30: group 10 (ESCO) | L30: group 10 (EPCO) | M30: group 12 (ESCO) | N30: group 17 (ESCO) | O30: group 13 (ESCO) | P30: group 13 (EPCO) | Q30: group 2 (CN2) | R30: group 4 (CN2) | S30: group 5 (CN2) | T30: group 7 (CN2) | U30: group 8 (CN2) | V30: group 10 (CN2) | W30: group 14 (CN2) | X30: group 12 (CN2) | Y30: group 17 (CN2) | Z30: group 13 (CN2)
A31: group 5 (GW_DELAY) | B31: group 5 (RCHRG_DP) | C31: group 10 (GW_REVAP) | D31: group 10 (RCHRG_DP) | E31: group 13 (RCHRG_DP) | F31: group 2 (ESCO) | G31: group 5 (ESCO) | H31: group 7 (ESCO) | I31: group 8 (ESCO) | J31: group 10 (ESCO) | K31: group 10 (EPCO) | L31: group 12 (ESCO) | M31: group 17 (ESCO) | N31: group 17 (EPCO) | O31: group 13 (ESCO) | P31: group 13 (EPCO) | Q31: group 2 (CN2) | R31: group 5 (CN2) | S31: group 7 (CN2) | T31: group 8 (CN2) | U31: group 10 (CN2) | V31: group 14 (CN2) | W31: group 12 (CN2) | X31: group 17 (CN2) | Y31: group 13 (CN2)
A32: group 1 (ESCO) | B32: group 3 (ESCO) | C32: group 4 (ESCO) | D32: group 14 (ESCO)
A33: group 5 (GW_DELAY) | B33: group 1 (ESCO) | C33: group 12 (ESCO) | D33: group 17 (ESCO) | E33: group 3 (CN2) | F33: group 2 (CN2) | G33: group 4 (CN2)
A34: group 13 (GW_DELAY) | B34: group 2 (ESCO) | C34: group 8 (ESCO) | D34: group 12 (ESCO) | E34: group 7 (CN2)
A35: group 13 (GW_DELAY) | B35: group 5 (ESCO)
A36: group 8 (RCHRG_DP) | B36: group 17 (RCHRG_DP) | C36: group 5 (ESCO) | D36: group 12 (ESCO)
A37: group 1 (ESCO) | B37: group 3 (ESCO) | C37: group 4 (ESCO) | D37: group 12 (ESCO) | E37: group 4 (CN2)
A38: group 8 (RCHRG_DP) | B38: group 12 (RCHRG_DP) | C38: group 13 (GW_DELAY) | D38: group 5 (ESCO) | E38: group 8 (ESCO) | F38: group 4 (CN2)
A39: group 12 (RCHRG_DP) | B39: group 1 (ESCO) | C39: group 2 (ESCO) | D39: group 5 (ESCO)
A40: group 12 (RCHRG_DP) | B40: group 13 (GW_DELAY) | C40: group 1 (ESCO) | D40: group 3 (ESCO) | E40: group 5 (ESCO)
...

Sheet Sheet2
A1: Year | B1: Type | C1: Method | D1: Group | F1: ParNums | G1: Unnamed: 6 | H1: Unnamed: 7 | I1: Unnamed: 8 | J1: Unnamed: 9 | K1: Unnamed: 10 | L1: Unnamed: 11 | M1: Unnamed: 12 | N1: Unnamed: 13 | O1: Unnamed: 14 | P1: Unnamed: 15 | Q1: Unnamed: 16 | R1: Unnamed: 17 | S1: Unnamed: 18 | T1: Unnamed: 19 | U1: Unnamed: 20 | V1: Unnamed: 21 | W1: Unnamed: 22 | X1: Unnamed: 23 | Y1: Unnamed: 24 | Z1: Unnamed: 25 | AA1: Unnamed: 26 | AB1: Unnamed: 27 | AC1: Unnamed: 28 | AD1: Unnamed: 29 | AE1: Unnamed: 30 | AF1: Unnamed: 31
A2: 2011 | B2: avg | C2: Quantile70_Group | D2: High importance & High interaction | F2: 5 | G2: 5 | H2: 7 | I2: 8 | J2: 8 | K2: 10 | L2: 10 | M2: 10 | N2: 12 | O2: 12 | P2: 17 | Q2: 13 | R2: 13 | S2: 13 | T2: 5 | U2: 10 | V2: 13 | W2: 2 | X2: 5 | Y2: 8 | Z2: 10 | AA2: 12 | AB2: 13
A3: 2012 | B3: avg | C3: Quantile70_Group | D3: High importance & High interaction | F3: 5 | G3: 5 | H3: 7 | I3: 8 | J3: 10 | K3: 10 | L3: 10 | M3: 10 | N3: 14 | O3: 12 | P3: 12 | Q3: 17 | R3: 17 | S3: 13 | T3: 13 | U3: 2 | V3: 5 | W3: 10 | X3: 13 | Y3: 2 | Z3: 5 | AA3: 7 | AB3: 8 | AC3: 10 | AD3: 17 | AE3: 13
A4: 2013 | B4: avg | C4: Quantile70_Group | D4: High importance & High interaction | F4: 5 | G4: 5 | H4: 7 | I4: 8 | J4: 10 | K4: 10 | L4: 10 | M4: 10 | N4: 12 | O4: 12 | P4: 12 | Q4: 17 | R4: 17 | S4: 13 | T4: 13 | U4: 13 | V4: 5 | W4: 8 | X4: 10 | Y4: 13 | Z4: 5 | AA4: 7 | AB4: 8 | AC4: 10 | AD4: 13
A5: 2014 | B5: avg | C5: Quantile70_Group | D5: High importance & High interaction | F5: 5 | G5: 8 | H5: 10 | I5: 10 | J5: 10 | K5: 12 | L5: 13 | M5: 13 | N5: 1 | O5: 2 | P5: 5 | Q5: 10 | R5: 13 | S5: 1 | T5: 3 | U5: 2 | V5: 4 | W5: 5 | X5: 7 | Y5: 8 | Z5: 10 | AA5: 12 | AB5: 17 | AC5: 13
A6: 2015 | B6: avg | C6: Quantile70_Group | D6: High importance & High interaction | F6: 5 | G6: 5 | H6: 5 | I6: 7 | J6: 8 | K6: 10 | L6: 10 | M6: 10 | N6: 12 | O6: 12 | P6: 12 | Q6: 17 | R6: 17 | S6: 13 | T6: 13 | U6: 13 | V6: 7 | W6: 8 | X6: 10 | Y6: 13 | Z6: 5 | AA6: 7 | AB6: 8 | AC6: 10 | AD6: 13
A7: 2016 | B7: avg | C7: Quantile70_Group | D7: High importance & High interaction | F7: 5 | G7: 5 | H7: 7 | I7: 8 | J7: 10 | K7: 10 | L7: 10 | M7: 10 | N7: 12 | O7: 17 | P7: 13 | Q7: 13 | R7: 2 | S7: 5 | T7: 10 | U7: 13 | V7: 2 | W7: 5 | X7: 7 | Y7: 8 | Z7: 10 | AA7: 12 | AB7: 17 | AC7: 13
A8: 2017 | B8: avg | C8: Quantile70_Group | D8: High importance & High interaction | F8: 5 | G8: 5 | H8: 5 | I8: 7 | J8: 8 | K8: 10 | L8: 10 | M8: 10 | N8: 10 | O8: 12 | P8: 12 | Q8: 12 | R8: 17 | S8: 13 | T8: 13 | U8: 5 | V8: 10 | W8: 12 | X8: 13 | Y8: 2 | Z8: 5 | AA8: 8 | AB8: 10 | AC8: 17 | AD8: 13
A9: 2018 | B9: avg | C9: Quantile70_Group | D9: High importance & High interaction | F9: 5 | G9: 5 | H9: 7 | I9: 8 | J9: 10 | K9: 10 | L9: 10 | M9: 10 | N9: 12 | O9: 12 | P9: 12 | Q9: 17 | R9: 13 | S9: 13 | T9: 13 | U9: 5 | V9: 8 | W9: 10 | X9: 12 | Y9: 13 | Z9: 2 | AA9: 5 | AB9: 8 | AC9: 10 | AD9: 17 | AE9: 13
A10: 2019 | B10: avg | C10: Quantile70_Group | D10: High importance & High interaction | F10: 5 | G10: 5 | H10: 5 | I10: 7 | J10: 8 | K10: 8 | L10: 10 | M10: 10 | N10: 10 | O10: 10 | P10: 12 | Q10: 12 | R10: 12 | S10: 17 | T10: 13 | U10: 13 | V10: 13 | W10: 13 | X10: 5 | Y10: 8 | Z10: 10 | AA10: 12 | AB10: 13 | AC10: 2 | AD10: 5 | AE10: 8 | AF10: 10
A11: 2020 | B11: avg | C11: Quantile70_Group | D11: High importance & High interaction | F11: 5 | G11: 5 | H11: 8 | I11: 10 | J11: 10 | K11: 10 | L11: 12 | M11: 17 | N11: 13 | O11: 13 | P11: 13 | Q11: 13 | R11: 2 | S11: 5 | T11: 8 | U11: 10 | V11: 12 | W11: 13 | X11: 2 | Y11: 4 | Z11: 5 | AA11: 8 | AB11: 10 | AC11: 17 | AD11: 13
A12: 2011 | B12: avg | C12: Quantile70_Group | D12: High importance & Low interaction | F12: 8 | G12: 17 | H12: 1 | I12: 3 | J12: 2 | K12: 8 | L12: 10 | M12: 12
A13: 2012 | B13: avg | C13: Quantile70_Group | D13: High importance & Low interaction | F13: 1 | G13: 3 | H13: 4 | I13: 8 | J13: 10 | K13: 12
A14: 2013 | B14: avg | C14: Quantile70_Group | D14: High importance & Low interaction | F14: 1 | G14: 14 | H14: 3 | I14: 2 | J14: 7 | K14: 12 | L14: 17
A15: 2014 | B15: avg | C15: Quantile70_Group | D15: High importance & Low interaction | F15: 7 | G15: 13 | H15: 3 | I15: 4 | J15: 7 | K15: 8 | L15: 12 | M15: 17
A16: 2015 | B16: avg | C16: Quantile70_Group | D16: High importance & Low interaction | F16: 10 | G16: 1 | H16: 3 | I16: 2 | J16: 4 | K16: 5 | L16: 12
A17: 2016 | B17: avg | C17: Quantile70_Group | D17: High importance & Low interaction | F17: 17 | G17: 1 | H17: 3 | I17: 4 | J17: 7 | K17: 8 | L17: 12 | M17: 17
A18: 2017 | B18: avg | C18: Quantile70_Group | D18: High importance & Low interaction | F18: 13 | G18: 1 | H18: 3 | I18: 2 | J18: 4 | K18: 7 | L18: 8 | M18: 17
A19: 2018 | B19: avg | C19: Quantile70_Group | D19: High importance & Low interaction | F19: 1 | G19: 3 | H19: 2 | I19: 4 | J19: 7 | K19: 17 | L19: 7
A20: 2019 | B20: avg | C20: Quantile70_Group | D20: High importance & Low interaction | F20: 17 | G20: 2 | H20: 7 | I20: 10 | J20: 17 | K20: 7
A21: 2020 | B21: avg | C21: Quantile70_Group | D21: High importance & Low interaction | F21: 7 | G21: 8 | H21: 1 | I21: 3 | J21: 4 | K21: 10 | L21: 17
A22: 2011 | B22: max | C22: Quantile70_Group | D22: High importance & High interaction | F22: 5 | G22: 5 | H22: 10 | I22: 10 | J22: 10 | K22: 13 | L22: 13 | M22: 13 | N22: 2 | O22: 5 | P22: 7 | Q22: 8 | R22: 10 | S22: 10 | T22: 12 | U22: 17 | V22: 13 | W22: 13 | X22: 2 | Y22: 5 | Z22: 7 | AA22: 8 | AB22: 10 | AC22: 14 | AD22: 12 | AE22: 17 | AF22: 13
A23: 2012 | B23: max | C23: Quantile70_Group | D23: High importance & High interaction | F23: 5 | G23: 10 | H23: 10 | I23: 10 | J23: 10 | K23: 13 | L23: 13 | M23: 2 | N23: 5 | O23: 8 | P23: 10 | Q23: 10 | R23: 13 | S23: 1 | T23: 5 | U23: 7 | V23: 8 | W23: 10 | X23: 14 | Y23: 12 | Z23: 17 | AA23: 13
A24: 2013 | B24: max | C24: Quantile70_Group | D24: High importance & High interaction | F24: 5 | G24: 5 | H24: 5 | I24: 8 | J24: 10 | K24: 10 | L24: 10 | M24: 10 | N24: 12 | O24: 12 | P24: 12 | Q24: 17 | R24: 13 | S24: 13 | T24: 3 | U24: 5 | V24: 10 | W24: 13 | X24: 3 | Y24: 2 | Z24: 4 | AA24: 8 | AB24: 10 | AC24: 12 | AD24: 13
A25: 2014 | B25: max | C25: Quantile70_Group | D25: High importance & High interaction | F25: 5 | G25: 5 | H25: 10 | I25: 10 | J25: 13 | K25: 13 | L25: 7 | M25: 8 | N25: 8 | O25: 10 | P25: 10 | Q25: 14 | R25: 12 | S25: 17 | T25: 13 | U25: 1 | V25: 3 | W25: 2 | X25: 4 | Y25: 5 | Z25: 7 | AA25: 8 | AB25: 10 | AC25: 14 | AD25: 12 | AE25: 17 | AF25: 13
A26: 2015 | B26: max | C26: Quantile70_Group | D26: High importance & High interaction | F26: 5 | G26: 5 | H26: 5 | I26: 7 | J26: 10 | K26: 10 | L26: 10 | M26: 10 | N26: 12 | O26: 17 | P26: 13 | Q26: 13 | R26: 13 | S26: 7 | T26: 8 | U26: 10 | V26: 13 | W26: 5 | X26: 7 | Y26: 8 | Z26: 10 | AA26: 14 | AB26: 12 | AC26: 17 | AD26: 13
A27: 2016 | B27: max | C27: Quantile70_Group | D27: High importance & High interaction | F27: 5 | G27: 10 | H27: 10 | I27: 10 | J27: 13 | K27: 2 | L27: 5 | M27: 7 | N27: 8 | O27: 10 | P27: 17 | Q27: 13 | R27: 1 | S27: 3 | T27: 2 | U27: 5 | V27: 7 | W27: 8 | X27: 10 | Y27: 14 | Z27: 12 | AA27: 17 | AB27: 13
A28: 2017 | B28: max | C28: Quantile70_Group | D28: High importance & High interaction | F28: 5 | G28: 5 | H28: 10 | I28: 10 | J28: 10 | K28: 10 | L28: 17 | M28: 13 | N28: 13 | O28: 10 | P28: 12 | Q28: 13 | R28: 1 | S28: 3 | T28: 2 | U28: 5 | V28: 7 | W28: 8 | X28: 10 | Y28: 14 | Z28: 12 | AA28: 17 | AB28: 13
A29: 2018 | B29: max | C29: Quantile70_Group | D29: High importance & High interaction | F29: 5 | G29: 5 | H29: 10 | I29: 10 | J29: 10 | K29: 12 | L29: 12 | M29: 17 | N29: 13 | O29: 13 | P29: 8 | Q29: 10 | R29: 10 | S29: 12 | T29: 13 | U29: 2 | V29: 5 | W29: 7 | X29: 8 | Y29: 10 | Z29: 14 | AA29: 12 | AB29: 17 | AC29: 13
A30: 2019 | B30: max | C30: Quantile70_Group | D30: High importance & High interaction | F30: 5 | G30: 5 | H30: 10 | I30: 10 | J30: 10 | K30: 13 | L30: 13 | M30: 13 | N30: 2 | O30: 8 | P30: 10 | Q30: 10 | R30: 12 | S30: 17 | T30: 13 | U30: 13 | V30: 2 | W30: 4 | X30: 5 | Y30: 7 | Z30: 8 | AA30: 10 | AB30: 14 | AC30: 12 | AD30: 17 | AE30: 13
A31: 2020 | B31: max | C31: Quantile70_Group | D31: High importance & High interaction | F31: 5 | G31: 5 | H31: 10 | I31: 10 | J31: 13 | K31: 2 | L31: 5 | M31: 7 | N31: 8 | O31: 10 | P31: 10 | Q31: 12 | R31: 17 | S31: 17 | T31: 13 | U31: 13 | V31: 2 | W31: 5 | X31: 7 | Y31: 8 | Z31: 10 | AA31: 14 | AB31: 12 | AC31: 17 | AD31: 13
A32: 2011 | B32: max | C32: Quantile70_Group | D32: High importance & Low interaction | F32: 1 | G32: 3 | H32: 4 | I32: 14
A33: 2012 | B33: max | C33: Quantile70_Group | D33: High importance & Low interaction | F33: 5 | G33: 1 | H33: 12 | I33: 17 | J33: 3 | K33: 2 | L33: 4
A34: 2013 | B34: max | C34: Quantile70_Group | D34: High importance & Low interaction | F34: 13 | G34: 2 | H34: 8 | I34: 12 | J34: 7
A35: 2014 | B35: max | C35: Quantile70_Group | D35: High importance & Low interaction | F35: 13 | G35: 5
A36: 2015 | B36: max | C36: Quantile70_Group | D36: High importance & Low interaction | F36: 8 | G36: 17 | H36: 5 | I36: 12
A37: 2016 | B37: max | C37: Quantile70_Group | D37: High importance & Low interaction | F37: 1 | G37: 3 | H37: 4 | I37: 12 | J37: 4
A38: 2017 | B38: max | C38: Quantile70_Group | D38: High importance & Low interaction | F38: 8 | G38: 12 | H38: 13 | I38: 5 | J38: 8 | K38: 4
A39: 2018 | B39: max | C39: Quantile70_Group | D39: High importance & Low interaction | F39: 12 | G39: 1 | H39: 2 | I39: 5
A40: 2019 | B40: max | C40: Quantile70_Group | D40: High importance & Low interaction | F40: 12 | G40: 13 | H40: 1 | I40: 3 | J40: 5
...

Sheet Sheet5

Sheet Subbasin group frequency
A1: X | B1: Avg HH | C1: Avg HL | D1: Max HH | E1: Max HL | F1: Min HH | G1: Min HL
A2: 1 | B2: =COUNTIF(Sheet2!$F$2:$Z$11,'Subbasin group frequency'!A2) -> 2 | C2: =COUNTIF(Sheet2!$E$12:$M$21,'Subbasin group frequency'!A2) -> 8 | D2: =COUNTIF(Sheet2!$E$22:$AF$31,'Subbasin group frequency'!A2) -> 4 | E2: =COUNTIF(Sheet2!$E$32:$XFD$41,'Subbasin group frequency'!A2) -> 5 | F2: =COUNTIF(Sheet2!$E$42:$AB$51,'Subbasin group frequency'!A2) -> 3 | G2: =COUNTIF(Sheet2!$E$52:$L$61,'Subbasin group frequency'!A2) -> 1
A3: 2 | B3: =COUNTIF(Sheet2!$F$2:$Z$11,'Subbasin group frequency'!A3) -> 11 | C3: =COUNTIF(Sheet2!$E$12:$M$21,'Subbasin group frequency'!A3) -> 6 | D3: =COUNTIF(Sheet2!$E$22:$AF$31,'Subbasin group frequency'!A3) -> 13 | E3: =COUNTIF(Sheet2!$E$32:$XFD$41,'Subbasin group frequency'!A3) -> 3 | F3: =COUNTIF(Sheet2!$E$42:$AB$51,'Subbasin group frequency'!A3) -> 11 | G3: =COUNTIF(Sheet2!$E$52:$L$61,'Subbasin group frequency'!A3) -> 5
A4: 3 | B4: =COUNTIF(Sheet2!$F$2:$Z$11,'Subbasin group frequency'!A4) -> 1 | C4: =COUNTIF(Sheet2!$E$12:$M$21,'Subbasin group frequency'!A4) -> 9 | D4: =COUNTIF(Sheet2!$E$22:$AF$31,'Subbasin group frequency'!A4) -> 5 | E4: =COUNTIF(Sheet2!$E$32:$XFD$41,'Subbasin group frequency'!A4) -> 4 | F4: =COUNTIF(Sheet2!$E$42:$AB$51,'Subbasin group frequency'!A4) -> 2 | G4: =COUNTIF(Sheet2!$E$52:$L$61,'Subbasin group frequency'!A4) -> 0
A5: 4 | B5: =COUNTIF(Sheet2!$F$2:$Z$11,'Subbasin group frequency'!A5) -> 2 | C5: =COUNTIF(Sheet2!$E$12:$M$21,'Subbasin group frequency'!A5) -> 7 | D5: =COUNTIF(Sheet2!$E$22:$AF$31,'Subbasin group frequency'!A5) -> 3 | E5: =COUNTIF(Sheet2!$E$32:$XFD$41,'Subbasin group frequency'!A5) -> 5 | F5: =COUNTIF(Sheet2!$E$42:$AB$51,'Subbasin group frequency'!A5) -> 4 | G5: =COUNTIF(Sheet2!$E$52:$L$61,'Subbasin group frequency'!A5) -> 0
A6: 5 | B6: =COUNTIF(Sheet2!$F$2:$Z$11,'Subbasin group frequency'!A6) -> 39 | C6: =COUNTIF(Sheet2!$E$12:$M$21,'Subbasin group frequency'!A6) -> 1 | D6: =COUNTIF(Sheet2!$E$22:$AF$31,'Subbasin group frequency'!A6) -> 34 | E6: =COUNTIF(Sheet2!$E$32:$XFD$41,'Subbasin group frequency'!A6) -> 6 | F6: =COUNTIF(Sheet2!$E$42:$AB$51,'Subbasin group frequency'!A6) -> 38 | G6: =COUNTIF(Sheet2!$E$52:$L$61,'Subbasin group frequency'!A6) -> 3
A7: 6 | B7: =COUNTIF(Sheet2!$F$2:$Z$11,'Subbasin group frequency'!A7) -> 0 | C7: =COUNTIF(Sheet2!$E$12:$M$21,'Subbasin group frequency'!A7) -> 0 | D7: =COUNTIF(Sheet2!$E$22:$AF$31,'Subbasin group frequency'!A7) -> 0 | E7: =COUNTIF(Sheet2!$E$32:$XFD$41,'Subbasin group frequency'!A7) -> 0 | F7: =COUNTIF(Sheet2!$E$42:$AB$51,'Subbasin group frequency'!A7) -> 0 | G7: =COUNTIF(Sheet2!$E$52:$L$61,'Subbasin group frequency'!A7) -> 0
A8: 7 | B8: =COUNTIF(Sheet2!$F$2:$Z$11,'Subbasin group frequency'!A8) -> 11 | C8: =COUNTIF(Sheet2!$E$12:$M$21,'Subbasin group frequency'!A8) -> 10 | D8: =COUNTIF(Sheet2!$E$22:$AF$31,'Subbasin group frequency'!A8) -> 15 | E8: =COUNTIF(Sheet2!$E$32:$XFD$41,'Subbasin group frequency'!A8) -> 1 | F8: =COUNTIF(Sheet2!$E$42:$AB$51,'Subbasin group frequency'!A8) -> 17 | G8: =COUNTIF(Sheet2!$E$52:$L$61,'Subbasin group frequency'!A8) -> 5
A9: 8 | B9: =COUNTIF(Sheet2!$F$2:$Z$11,'Subbasin group frequency'!A9) -> 20 | C9: =COUNTIF(Sheet2!$E$12:$M$21,'Subbasin group frequency'!A9) -> 7 | D9: =COUNTIF(Sheet2!$E$22:$AF$31,'Subbasin group frequency'!A9) -> 20 | E9: =COUNTIF(Sheet2!$E$32:$XFD$41,'Subbasin group frequency'!A9) -> 4 | F9: =COUNTIF(Sheet2!$E$42:$AB$51,'Subbasin group frequency'!A9) -> 34 | G9: =COUNTIF(Sheet2!$E$52:$L$61,'Subbasin group frequency'!A9) -> 6
A10: 9 | B10: =COUNTIF(Sheet2!$F$2:$Z$11,'Subbasin group frequency'!A10) -> 0 | C10: =COUNTIF(Sheet2!$E$12:$M$21,'Subbasin group frequency'!A10) -> 0 | D10: =COUNTIF(Sheet2!$E$22:$AF$31,'Subbasin group frequency'!A10) -> 0 | E10: =COUNTIF(Sheet2!$E$32:$XFD$41,'Subbasin group frequency'!A10) -> 0 | F10: =COUNTIF(Sheet2!$E$42:$AB$51,'Subbasin group frequency'!A10) -> 0 | G10: =COUNTIF(Sheet2!$E$52:$L$61,'Subbasin group frequency'!A10) -> 0
A11: 10 | B11: =COUNTIF(Sheet2!$F$2:$Z$11,'Subbasin group frequency'!A11) -> 49 | C11: =COUNTIF(Sheet2!$E$12:$M$21,'Subbasin group frequency'!A11) -> 5 | D11: =COUNTIF(Sheet2!$E$22:$AF$31,'Subbasin group frequency'!A11) -> 58 | E11: =COUNTIF(Sheet2!$E$32:$XFD$41,'Subbasin group frequency'!A11) -> 1 | F11: =COUNTIF(Sheet2!$E$42:$AB$51,'Subbasin group frequency'!A11) -> 44 | G11: =COUNTIF(Sheet2!$E$52:$L$61,'Subbasin group frequency'!A11) -> 0
A12: 11 | B12: =COUNTIF(Sheet2!$F$2:$Z$11,'Subbasin group frequency'!A12) -> 0 | C12: =COUNTIF(Sheet2!$E$12:$M$21,'Subbasin group frequency'!A12) -> 0 | D12: =COUNTIF(Sheet2!$E$22:$AF$31,'Subbasin group frequency'!A12) -> 0 | E12: =COUNTIF(Sheet2!$E$32:$XFD$41,'Subbasin group frequency'!A12) -> 0 | F12: =COUNTIF(Sheet2!$E$42:$AB$51,'Subbasin group frequency'!A12) -> 0 | G12: =COUNTIF(Sheet2!$E$52:$L$61,'Subbasin group frequency'!A12) -> 0
A13: 12 | B13: =COUNTIF(Sheet2!$F$2:$Z$11,'Subbasin group frequency'!A13) -> 25 | C13: =COUNTIF(Sheet2!$E$12:$M$21,'Subbasin group frequency'!A13) -> 6 | D13: =COUNTIF(Sheet2!$E$22:$AF$31,'Subbasin group frequency'!A13) -> 22 | E13: =COUNTIF(Sheet2!$E$32:$XFD$41,'Subbasin group frequency'!A13) -> 7 | F13: =COUNTIF(Sheet2!$E$42:$AB$51,'Subbasin group frequency'!A13) -> 20 | G13: =COUNTIF(Sheet2!$E$52:$L$61,'Subbasin group frequency'!A13) -> 14
... A23: 22 | B23: =COUNTIF(Sheet2!$F$2:$Z$11,'Subbasin group frequency'!A23) -> 0 | C23: =COUNTIF(Sheet2!$E$12:$M$21,'Subbasin group frequency'!A23) -> 0 | D23: =COUNTIF(Sheet2!$E$22:$AF$31,'Subbasin group frequency'!A23) -> 0 | E23: =COUNTIF(Sheet2!$E$32:$XFD$41,'Subbasin group frequency'!A23) -> 0 | F23: =COUNTIF(Sheet2!$E$42:$AB$51,'Subbasin group frequency'!A23) -> 0 | G23: =COUNTIF(Sheet2!$E$52:$L$61,'Subbasin group frequency'!A23) -> 0
A24: S1 | B24: =COUNTIF(Sheet2!$F$2:$Z$11,'Subbasin group frequency'!A24) -> 0 | C24: =COUNTIF(Sheet2!$E$12:$M$21,'Subbasin group frequency'!A24) -> 0 | D24: =COUNTIF(Sheet2!$E$22:$AF$31,'Subbasin group frequency'!A24) -> 0 | E24: =COUNTIF(Sheet2!$E$32:$XFD$41,'Subbasin group frequency'!A24) -> 0 | F24: =COUNTIF(Sheet2!$E$42:$AB$51,'Subbasin group frequency'!A24) -> 0 | G24: =COUNTIF(Sheet2!$E$52:$L$61,'Subbasin group frequency'!A24) -> 0
A25: S2 | B25: =COUNTIF(Sheet2!$F$2:$Z$11,'Subbasin group frequency'!A25) -> 0 | C25: =COUNTIF(Sheet2!$E$12:$M$21,'Subbasin group frequency'!A25) -> 0 | D25: =COUNTIF(Sheet2!$E$22:$AF$31,'Subbasin group frequency'!A25) -> 0 | E25: =COUNTIF(Sheet2!$E$32:$XFD$41,'Subbasin group frequency'!A25) -> 0 | F25: =COUNTIF(Sheet2!$E$42:$AB$51,'Subbasin group frequency'!A25) -> 0 | G25: =COUNTIF(Sheet2!$E$52:$L$61,'Subbasin group frequency'!A25) -> 0
A26: A | B26: =COUNTIF(Sheet2!$F$2:$Z$11,'Subbasin group frequency'!A26) -> 0 | C26: =COUNTIF(Sheet2!$E$12:$M$21,'Subbasin group frequency'!A26) -> 0 | D26: =COUNTIF(Sheet2!$E$22:$AF$31,'Subbasin group frequency'!A26) -> 0 | E26: =COUNTIF(Sheet2!$E$32:$XFD$41,'Subbasin group frequency'!A26) -> 0 | F26: =COUNTIF(Sheet2!$E$42:$AB$51,'Subbasin group frequency'!A26) -> 0 | G26: =COUNTIF(Sheet2!$E$52:$L$61,'Subbasin group frequency'!A26) -> 0
