Workbook

Sheet Sheet1
A1: Year | B1: Type | C1: Method | D1: Group | E1: Count | F1: ParNums
A2: 2011 | B2: avg | C2: Quantile70_Group | D2: High importance & High interaction | E2: 23 | F2: par74 | G2: par77 | H2: par83 | I2: par84 | J2: par89 | K2: par90 | L2: par92 | M2: par95 | N2: par106 | O2: par107 | P2: par110 | Q2: par116 | R2: par118 | S2: par119 | T2: par172 | U2: par181 | V2: par193 | W2: par215 | X2: par218 | Y2: par220 | Z2: par221 | AA2: par223 | AB2: par225
A3: 2011 | B3: avg | C3: Quantile70_Group | D3: High importance & Low interaction | E3: 8 | F3: par86 | G3: par113 | H3: par157 | I3: par160 | J3: par163 | K3: par178 | L3: par182 | M3: par187
A4: 2012 | B4: avg | C4: Quantile70_Group | D4: High importance & High interaction | E4: 26 | F4: par72 | G4: par77 | H4: par83 | I4: par89 | J4: par90 | K4: par92 | L4: par94 | M4: par95 | N4: par100 | O4: par106 | P4: par107 | Q4: par112 | R4: par113 | S4: par118 | T4: par119 | U4: par163 | V4: par172 | W4: par181 | X4: par193 | Y4: par215 | Z4: par218 | AA4: par219 | AB4: par220 | AC4: par221 | AD4: par224 | AE4: par225
A5: 2012 | B5: avg | C5: Quantile70_Group | D5: High importance & Low interaction | E5: 6 | F5: par157 | G5: par160 | H5: par166 | I5: par178 | J5: par182 | K5: par187
A6: 2013 | B6: avg | C6: Quantile70_Group | D6: High importance & High interaction | E6: 25 | F6: par72 | G6: par77 | H6: par83 | I6: par89 | J6: par90 | K6: par92 | L6: par94 | M6: par95 | N6: par102 | O6: par106 | P6: par107 | Q6: par112 | R6: par113 | S6: par116 | T6: par118 | U6: par119 | V6: par172 | W6: par178 | X6: par181 | Y6: par193 | Z6: par218 | AA6: par219 | AB6: par220 | AC6: par221 | AD6: par225
A7: 2013 | B7: avg | C7: Quantile70_Group | D7: High importance & Low interaction | E7: 7 | F7: par47 | G7: par101 | H7: par160 | I7: par163 | J7: par175 | K7: par187 | L7: par190
A8: 2014 | B8: avg | C8: Quantile70_Group | D8: High importance & High interaction | E8: 24 | F8: par77 | G8: par89 | H8: par90 | I8: par92 | J8: par95 | K8: par107 | L8: par118 | M8: par119 | N8: par157 | O8: par163 | P8: par172 | Q8: par181 | R8: par193 | S8: par213 | T8: par214 | U8: par215 | V8: par216 | W8: par218 | X8: par219 | Y8: par220 | Z8: par221 | AA8: par223 | AB8: par224 | AC8: par225
A9: 2014 | B9: avg | C9: Quantile70_Group | D9: High importance & Low interaction | E9: 8 | F9: par83 | G9: par116 | H9: par160 | I9: par166 | J9: par175 | K9: par178 | L9: par187 | M9: par190
A10: 2015 | B10: avg | C10: Quantile70_Group | D10: High importance & High interaction | E10: 25 | F10: par72 | G10: par74 | H10: par77 | I10: par83 | J10: par89 | K10: par90 | L10: par94 | M10: par95 | N10: par102 | O10: par106 | P10: par107 | Q10: par112 | R10: par113 | S10: par116 | T10: par118 | U10: par119 | V10: par175 | W10: par178 | X10: par181 | Y10: par193 | Z10: par218 | AA10: par219 | AB10: par220 | AC10: par221 | AD10: par225
A11: 2015 | B11: avg | C11: Quantile70_Group | D11: High importance & Low interaction | E11: 7 | F11: par92 | G11: par157 | H11: par160 | I11: par163 | J11: par166 | K11: par172 | L11: par187
A12: 2016 | B12: avg | C12: Quantile70_Group | D12: High importance & High interaction | E12: 24 | F12: par72 | G12: par77 | H12: par83 | I12: par89 | J12: par90 | K12: par92 | L12: par94 | M12: par95 | N12: par107 | O12: par112 | P12: par118 | Q12: par119 | R12: par163 | S12: par172 | T12: par181 | U12: par193 | V12: par215 | W12: par218 | X12: par219 | Y12: par220 | Z12: par221 | AA12: par223 | AB12: par224 | AC12: par225
A13: 2016 | B13: avg | C13: Quantile70_Group | D13: High importance & Low interaction | E13: 8 | F13: par113 | G13: par157 | H13: par160 | I13: par166 | J13: par175 | K13: par178 | L13: par187 | M13: par190
A14: 2017 | B14: avg | C14: Quantile70_Group | D14: High importance & High interaction | E14: 25 | F14: par72 | G14: par74 | H14: par77 | I14: par83 | J14: par89 | K14: par90 | L14: par92 | M14: par94 | N14: par95 | O14: par102 | P14: par106 | Q14: par107 | R14: par112 | S14: par118 | T14: par119 | U14: par172 | V14: par181 | W14: par187 | X14: par193 | Y14: par215 | Z14: par218 | AA14: par220 | AB14: par221 | AC14: par224 | AD14: par225
A15: 2017 | B15: avg | C15: Quantile70_Group | D15: High importance & Low interaction | E15: 8 | F15: par116 | G15: par157 | H15: par160 | I15: par163 | J15: par166 | K15: par175 | L15: par178 | M15: par190
A16: 2018 | B16: avg | C16: Quantile70_Group | D16: High importance & High interaction | E16: 26 | F16: par72 | G16: par77 | H16: par83 | I16: par89 | J16: par90 | K16: par92 | L16: par94 | M16: par95 | N16: par102 | O16: par106 | P16: par107 | Q16: par112 | R16: par114 | S16: par118 | T16: par119 | U16: par172 | V16: par178 | W16: par181 | X16: par187 | Y16: par193 | Z16: par215 | AA16: par218 | AB16: par220 | AC16: par221 | AD16: par224 | AE16: par225
A17: 2018 | B17: avg | C17: Quantile70_Group | D17: High importance & Low interaction | E17: 7 | F17: par157 | G17: par160 | H17: par163 | I17: par166 | J17: par175 | K17: par190 | L17: par219
A18: 2019 | B18: avg | C18: Quantile70_Group | D18: High importance & High interaction | E18: 27 | F18: par72 | G18: par74 | H18: par77 | I18: par83 | J18: par86 | K18: par89 | L18: par90 | M18: par92 | N18: par94 | O18: par95 | P18: par102 | Q18: par106 | R18: par107 | S18: par110 | T18: par114 | U18: par116 | V18: par118 | W18: par119 | X18: par172 | Y18: par178 | Z18: par181 | AA18: par187 | AB18: par193 | AC18: par215 | AD18: par218 | AE18: par220 | AF18: par221
A19: 2019 | B19: avg | C19: Quantile70_Group | D19: High importance & Low interaction | E19: 6 | F19: par113 | G19: par163 | H19: par175 | I19: par182 | J19: par190 | K19: par219
A20: 2020 | B20: avg | C20: Quantile70_Group | D20: High importance & High interaction | E20: 25 | F20: par74 | G20: par77 | H20: par89 | I20: par90 | J20: par92 | K20: par95 | L20: par107 | M20: par113 | N20: par114 | O20: par116 | P20: par118 | Q20: par119 | R20: par163 | S20: par172 | T20: par178 | U20: par181 | V20: par187 | W20: par193 | X20: par215 | Y20: par216 | Z20: par218 | AA20: par220 | AB20: par221 | AC20: par224 | AD20: par225
A21: 2020 | B21: avg | C21: Quantile70_Group | D21: High importance & Low interaction | E21: 7 | F21: par83 | G21: par86 | H21: par157 | I21: par160 | J21: par166 | K21: par182 | L21: par190
A22: 2011 | B22: max | C22: Quantile70_Group | D22: High importance & High interaction | E22: 27 | F22: par74 | G22: par77 | H22: par90 | I22: par92 | J22: par95 | K22: par116 | L22: par118 | M22: par119 | N22: par163 | O22: par172 | P22: par175 | Q22: par178 | R22: par181 | S22: par182 | T22: par187 | U22: par190 | V22: par193 | W22: par194 | X22: par215 | Y22: par218 | Z22: par219 | AA22: par220 | AB22: par221 | AC22: par222 | AD22: par223 | AE22: par224 | AF22: par225
A23: 2011 | B23: max | C23: Quantile70_Group | D23: High importance & Low interaction | E23: 4 | F23: par157 | G23: par160 | H23: par166 | I23: par184
A24: 2012 | B24: max | C24: Quantile70_Group | D24: High importance & High interaction | E24: 22 | F24: par77 | G24: par90 | H24: par92 | I24: par94 | J24: par95 | K24: par118 | L24: par119 | M24: par163 | N24: par172 | O24: par178 | P24: par181 | Q24: par182 | R24: par193 | S24: par213 | T24: par218 | U24: par219 | V24: par220 | W24: par221 | X24: par222 | Y24: par223 | Z24: par224 | AA24: par225
A25: 2012 | B25: max | C25: Quantile70_Group | D25: High importance & Low interaction | E25: 7 | F25: par74 | G25: par157 | H25: par187 | I25: par190 | J25: par214 | K25: par215 | L25: par216
A26: 2013 | B26: max | C26: Quantile70_Group | D26: High importance & High interaction | E26: 25 | F26: par72 | G26: par74 | H26: par77 | I26: par89 | J26: par90 | K26: par92 | L26: par94 | M26: par95 | N26: par102 | O26: par106 | P26: par107 | Q26: par112 | R26: par118 | S26: par119 | T26: par160 | U26: par172 | V26: par181 | W26: par193 | X26: par214 | Y26: par215 | Z26: par216 | AA26: par220 | AB26: par221 | AC26: par223 | AD26: par225
A27: 2013 | B27: max | C27: Quantile70_Group | D27: High importance & Low interaction | E27: 5 | F27: par116 | G27: par163 | H27: par178 | I27: par187 | J27: par219
A28: 2014 | B28: max | C28: Quantile70_Group | D28: High importance & High interaction | E28: 27 | F28: par74 | G28: par77 | H28: par92 | I28: par95 | J28: par118 | K28: par119 | L28: par175 | M28: par178 | N28: par179 | O28: par181 | P28: par182 | Q28: par184 | R28: par187 | S28: par190 | T28: par193 | U28: par213 | V28: par214 | W28: par215 | X28: par216 | Y28: par218 | Z28: par219 | AA28: par220 | AB28: par221 | AC28: par222 | AD28: par223 | AE28: par224 | AF28: par225
A29: 2014 | B29: max | C29: Quantile70_Group | D29: High importance & Low interaction | E29: 2 | F29: par116 | G29: par172
A30: 2015 | B30: max | C30: Quantile70_Group | D30: High importance & High interaction | E30: 25 | F30: par72 | G30: par74 | H30: par77 | I30: par83 | J30: par90 | K30: par92 | L30: par94 | M30: par95 | N30: par107 | O30: par112 | P30: par116 | Q30: par118 | R30: par119 | S30: par175 | T30: par178 | U30: par181 | V30: par193 | W30: par218 | X30: par219 | Y30: par220 | Z30: par221 | AA30: par222 | AB30: par223 | AC30: par224 | AD30: par225
A31: 2015 | B31: max | C31: Quantile70_Group | D31: High importance & Low interaction | E31: 4 | F31: par89 | G31: par113 | H31: par172 | I31: par187
A32: 2016 | B32: max | C32: Quantile70_Group | D32: High importance & High interaction | E32: 23 | F32: par77 | G32: par90 | H32: par92 | I32: par95 | J32: par119 | K32: par163 | L32: par172 | M32: par175 | N32: par178 | O32: par181 | P32: par190 | Q32: par193 | R32: par213 | S32: par214 | T32: par215 | U32: par218 | V32: par219 | W32: par220 | X32: par221 | Y32: par222 | Z32: par223 | AA32: par224 | AB32: par225
A33: 2016 | B33: max | C33: Quantile70_Group | D33: High importance & Low interaction | E33: 5 | F33: par157 | G33: par160 | H33: par166 | I33: par187 | J33: par216
A34: 2017 | B34: max | C34: Quantile70_Group | D34: High importance & High interaction | E34: 23 | F34: par72 | G34: par77 | H34: par90 | I34: par92 | J34: par94 | K34: par95 | L34: par112 | M34: par118 | N34: par119 | O34: par181 | P34: par187 | Q34: par193 | R34: par213 | S34: par214 | T34: par215 | U34: par218 | V34: par219 | W34: par220 | X34: par221 | Y34: par222 | Z34: par223 | AA34: par224 | AB34: par225
A35: 2017 | B35: max | C35: Quantile70_Group | D35: High importance & Low interaction | E35: 6 | F35: par89 | G35: par107 | H35: par116 | I35: par172 | J35: par178 | K35: par216
A36: 2018 | B36: max | C36: Quantile70_Group | D36: High importance & High interaction | E36: 24 | F36: par72 | G36: par77 | H36: par92 | I36: par94 | J36: par95 | K36: par102 | L36: par106 | M36: par112 | N36: par118 | O36: par119 | P36: par178 | Q36: par181 | R36: par182 | S36: par187 | T36: par193 | U36: par215 | V36: par218 | W36: par219 | X36: par220 | Y36: par221 | Z36: par222 | AA36: par223 | AB36: par224 | AC36: par225
A37: 2018 | B37: max | C37: Quantile70_Group | D37: High importance & Low interaction | E37: 4 | F37: par107 | G37: par157 | H37: par163 | I37: par172
A38: 2019 | B38: max | C38: Quantile70_Group | D38: High importance & High interaction | E38: 26 | F38: par72 | G38: par77 | H38: par90 | I38: par92 | J38: par95 | K38: par114 | L38: par118 | M38: par119 | N38: par163 | O38: par178 | P38: par181 | Q38: par182 | R38: par187 | S38: par190 | T38: par193 | U38: par194 | V38: par215 | W38: par216 | X38: par218 | Y38: par219 | Z38: par220 | AA38: par221 | AB38: par222 | AC38: par223 | AD38: par224 | AE38: par225
A39: 2019 | B39: max | C39: Quantile70_Group | D39: High importance & Low interaction | E39: 5 | F39: par107 | G39: par116 | H39: par157 | I39: par160 | J39: par172
A40: 2020 | B40: max | C40: Quantile70_Group | D40: High importance & High interaction | E40: 25 | F40: par74 | G40: par77 | H40: par90 | I40: par95 | J40: par119 | K40: par163 | L40: par172 | M40: par175 | N40: par178 | O40: par181 | P40: par182 | Q40: par187 | R40: par190 | S40: par191 | T40: par193 | U40: par194 | V40: par215 | W40: par218 | X40: par219 | Y40: par220 | Z40: par221 | AA40: par222 | AB40: par223 | AC40: par224 | AD40: par225
...

Sheet allcase
A1: ParNum | B1: Count | D1: ParNum | E1: Count | G1: ParNum | H1: =COUNT(H2:H56) -> 55 | J1: ParNum | K1: =COUNT(K2:K48) -> 47 | M1: ParNum | N1: =COUNT(N2:N38) -> 37 | P1: ParNum | Q1: Count
A2: Par1 | B2: =COUNTIF(Sheet1!$F$2:$AG$60,allcase!A2) -> 0 | D2: Par77 | E2: 30 | G2: Par47 | H2: 2 | J2: Par72 | K2: 14 | M2: Par72 | N2: 14 | P2: Par47 | Q2: 2 | R2: RCHRG_DP | U2: =37+1 -> 38 | V2: 32
A3: Par2 | B3: =COUNTIF(Sheet1!$F$2:$AG$60,allcase!A3) -> 0 | D3: Par92 | E3: 30 | G3: Par72 | H3: 14 | J3: Par74 | K3: 19 | M3: Par74 | N3: 19 | P3: Par84 | Q3: 5 | R3: GW_REVAP | V3: =U2*V2 -> 1216
A4: Par3 | B4: =COUNTIF(Sheet1!$F$2:$AG$60,allcase!A4) -> 0 | D4: Par95 | E4: 30 | G4: Par74 | H4: 19 | J4: Par77 | K4: 30 | M4: Par77 | N4: 30 | P4: Par98 | Q4: 3 | R4: GW_DELAY | U4: =37*2+2 -> 76 | V4: 500
A5: Par4 | B5: =COUNTIF(Sheet1!$F$2:$AG$60,allcase!A5) -> 0 | D5: Par119 | E5: 30 | G5: Par77 | H5: 30 | J5: Par83 | K5: 20 | M5: Par83 | N5: 20 | P5: Par100 | Q5: 1 | R5: GWQMN | V5: =U4*V4 -> 38000
A6: Par5 | B6: =COUNTIF(Sheet1!$F$2:$AG$60,allcase!A6) -> 0 | D6: Par172 | E6: 30 | G6: Par83 | H6: 20 | J6: Par84 | K6: 5 | M6: Par86 | N6: 11 | P6: Par101 | Q6: 5 | R6: RCHRG_DP
A7: Par6 | B7: =COUNTIF(Sheet1!$F$2:$AG$60,allcase!A7) -> 0 | D7: Par178 | E7: 30 | G7: Par84 | H7: 5 | J7: Par86 | K7: 11 | M7: Par89 | N7: 23 | P7: Par102 | Q7: 9 | R7: GW_REVAP | V7: 28672 | W7: =V7/800 -> 35.84 | X7: =V7/400 -> 71.68
A8: Par7 | B8: =COUNTIF(Sheet1!$F$2:$AG$60,allcase!A8) -> 0 | D8: Par181 | E8: 30 | G8: Par86 | H8: 11 | J8: Par89 | K8: 23 | M8: Par90 | N8: 22 | P8: Par104 | Q8: 5 | R8: GW_DELAY
A9: Par8 | B9: =COUNTIF(Sheet1!$F$2:$AG$60,allcase!A9) -> 0 | D9: Par193 | E9: 30 | G9: Par89 | H9: 23 | J9: Par90 | K9: 22 | M9: Par92 | N9: 30 | P9: Par110 | Q9: 7 | R9: GW_DELAY
A10: Par9 | B10: =COUNTIF(Sheet1!$F$2:$AG$60,allcase!A10) -> 0 | D10: Par221 | E10: 30 | G10: Par90 | H10: 22 | J10: Par92 | K10: 30 | M10: Par94 | N10: 13 | P10: Par114 | Q10: 6 | R10: GW_REVAP
A11: Par10 | B11: =COUNTIF(Sheet1!$F$2:$AG$60,allcase!A11) -> 0 | D11: Par187 | E11: 29 | G11: Par92 | H11: 30 | J11: Par94 | K11: 13 | M11: Par95 | N11: 30 | P11: Par166 | Q11: 9 | R11: ESCO | V11: 1simulation | W11: 20min | X11: 1hour 3 simulation
A12: Par11 | B12: =COUNTIF(Sheet1!$F$2:$AG$60,allcase!A12) -> 0 | D12: Par218 | E12: 29 | G12: Par94 | H12: 13 | J12: Par95 | K12: 30 | M12: Par106 | N12: 14 | P12: Par173 | Q12: 1 | R12: EPCO | X12: 24 hour 72
A13: Par12 | B13: =COUNTIF(Sheet1!$F$2:$AG$60,allcase!A13) -> 0 | D13: Par220 | E13: 29 | G13: Par95 | H13: 30 | J13: Par101 | K13: 5 | M13: Par107 | N13: 25 | P13: Par179 | Q13: 1 | R13: EPCO | V13: 1computer can do 10 parallel
A14: Par13 | B14: =COUNTIF(Sheet1!$F$2:$AG$60,allcase!A14) -> 0 | D14: Par225 | E14: 29 | G14: Par98 | H14: 3 | J14: Par102 | K14: 9 | M14: Par112 | N14: 11 | P14: Par184 | Q14: 3 | R14: ESCO | V14: 24hour 720 simulation
A15: Par14 | B15: =COUNTIF(Sheet1!$F$2:$AG$60,allcase!A15) -> 0 | D15: Par219 | E15: 27 | G15: Par100 | H15: 1 | J15: Par104 | K15: 5 | M15: Par113 | N15: 17 | P15: Par191 | Q15: 1 | R15: EPCO | V15: werl01 | W15: 5 parallel
A16: Par15 | B16: =COUNTIF(Sheet1!$F$2:$AG$60,allcase!A16) -> 0 | D16: Par215 | E16: 26 | G16: Par101 | H16: 5 | J16: Par106 | K16: 14 | M16: Par116 | N16: 24 | P16: Par194 | Q16: 3 | R16: EPCO | V16: werl03 | W16: 10 parallel
A17: Par16 | B17: =COUNTIF(Sheet1!$F$2:$AG$60,allcase!A17) -> 0 | D17: Par107 | E17: 25 | G17: Par102 | H17: 9 | J17: Par107 | K17: 25 | M17: Par118 | N17: 24 | P17: Par213 | Q17: 6 | R17: CN2 | V17: office desktop | W17: 10parallel
A18: Par17 | B18: =COUNTIF(Sheet1!$F$2:$AG$60,allcase!A18) -> 0 | D18: Par116 | E18: 24 | G18: Par104 | H18: 5 | J18: Par110 | K18: 7 | M18: Par119 | N18: 30 | P18: Par214 | Q18: 8 | R18: CN2 | V18: my home | W18: 10 parallel
A19: Par18 | B19: =COUNTIF(Sheet1!$F$2:$AG$60,allcase!A19) -> 0 | D19: Par118 | E19: 24 | G19: Par106 | H19: 14 | J19: Par112 | K19: 11 | M19: Par157 | N19: 15 | P19: Par222 | Q19: 9 | R19: CN2 | V19: other pc | W19: 10 parallel
A20: Par19 | B20: =COUNTIF(Sheet1!$F$2:$AG$60,allcase!A20) -> 0 | D20: Par89 | E20: 23 | G20: Par107 | H20: 25 | J20: Par113 | K20: 17 | M20: Par160 | N20: 13 | V20: 45 simulation at one time
A21: Par20 | B21: =COUNTIF(Sheet1!$F$2:$AG$60,allcase!A21) -> 0 | D21: Par163 | E21: 23 | G21: Par110 | H21: 7 | J21: Par114 | K21: 6 | M21: Par163 | N21: 23 | V21: 45 | W21: 72 | X21: =V21*W21 -> 3240 | Y21: simulation per day
A22: Par21 | B22: =COUNTIF(Sheet1!$F$2:$AG$60,allcase!A22) -> 0 | D22: Par90 | E22: 22 | G22: Par112 | H22: 11 | J22: Par116 | K22: 24 | M22: Par172 | N22: 30 | X22: =28672/X21 -> 8.8493827 | Y22: 10days to run 28672
A23: Par22 | B23: =COUNTIF(Sheet1!$F$2:$AG$60,allcase!A23) -> 0 | D23: Par224 | E23: 22 | G23: Par113 | H23: 17 | J23: Par118 | K23: 24 | M23: Par175 | N23: 15
A24: Par23 | B24: =COUNTIF(Sheet1!$F$2:$AG$60,allcase!A24) -> 0 | D24: Par83 | E24: 20 | G24: Par114 | H24: 6 | J24: Par119 | K24: 30 | M24: Par178 | N24: 30
A25: Par24 | B25: =COUNTIF(Sheet1!$F$2:$AG$60,allcase!A25) -> 0 | D25: Par74 | E25: 19 | G25: Par116 | H25: 24 | J25: Par157 | K25: 15 | M25: Par181 | N25: 30
A26: Par25 | B26: =COUNTIF(Sheet1!$F$2:$AG$60,allcase!A26) -> 0 | D26: Par113 | E26: 17 | G26: Par118 | H26: 24 | J26: Par160 | K26: 13 | M26: Par182 | N26: 11
A27: Par26 | B27: =COUNTIF(Sheet1!$F$2:$AG$60,allcase!A27) -> 0 | D27: Par190 | E27: 17 | G27: Par119 | H27: 30 | J27: Par163 | K27: 23 | M27: Par187 | N27: 29
A28: Par27 | B28: =COUNTIF(Sheet1!$F$2:$AG$60,allcase!A28) -> 0 | D28: Par157 | E28: 15 | G28: Par157 | H28: 15 | J28: Par166 | K28: 9 | M28: Par190 | N28: 17
A29: Par28 | B29: =COUNTIF(Sheet1!$F$2:$AG$60,allcase!A29) -> 0 | D29: Par175 | E29: 15 | G29: Par160 | H29: 13 | J29: Par172 | K29: 30 | M29: Par193 | N29: 30
A30: Par29 | B30: =COUNTIF(Sheet1!$F$2:$AG$60,allcase!A30) -> 0 | D30: Par223 | E30: 15 | G30: Par163 | H30: 23 | J30: Par175 | K30: 15 | M30: Par215 | N30: 26
A31: Par30 | B31: =COUNTIF(Sheet1!$F$2:$AG$60,allcase!A31) -> 0 | D31: Par72 | E31: 14 | G31: Par166 | H31: 9 | J31: Par178 | K31: 30 | M31: Par216 | N31: 12
A32: Par31 | B32: =COUNTIF(Sheet1!$F$2:$AG$60,allcase!A32) -> 0 | D32: Par106 | E32: 14 | G32: Par172 | H32: 30 | J32: Par181 | K32: 30 | M32: Par218 | N32: 29
A33: Par32 | B33: =COUNTIF(Sheet1!$F$2:$AG$60,allcase!A33) -> 0 | D33: Par94 | E33: 13 | G33: Par173 | H33: 1 | J33: Par182 | K33: 11 | M33: Par219 | N33: 27
A34: Par33 | B34: =COUNTIF(Sheet1!$F$2:$AG$60,allcase!A34) -> 0 | D34: Par160 | E34: 13 | G34: Par175 | H34: 15 | J34: Par187 | K34: 29 | M34: Par220 | N34: 29
... A38: Par37 | B38: =COUNTIF(Sheet1!$F$2:$AG$60,allcase!A38) -> 0 | D38: Par182 | E38: 11 | G38: Par182 | H38: 11 | J38: Par214 | K38: 8 | M38: Par225 | N38: 29
A39: Par38 | B39: =COUNTIF(Sheet1!$F$2:$AG$60,allcase!A39) -> 0 | D39: Par102 | E39: 9 | G39: Par184 | H39: 3 | J39: Par215 | K39: 26
A40: Par39 | B40: =COUNTIF(Sheet1!$F$2:$AG$60,allcase!A40) -> 0 | D40: Par166 | E40: 9 | G40: Par187 | H40: 29 | J40: Par216 | K40: 12
A41: Par40 | B41: =COUNTIF(Sheet1!$F$2:$AG$60,allcase!A41) -> 0 | D41: Par222 | E41: 9 | G41: Par190 | H41: 17 | J41: Par218 | K41: 29
A42: Par41 | B42: =COUNTIF(Sheet1!$F$2:$AG$60,allcase!A42) -> 0 | D42: Par214 | E42: 8 | G42: Par191 | H42: 1 | J42: Par219 | K42: 27
A43: Par42 | B43: =COUNTIF(Sheet1!$F$2:$AG$60,allcase!A43) -> 0 | D43: Par110 | E43: 7 | G43: Par193 | H43: 30 | J43: Par220 | K43: 29
...

Sheet avg
A1: ParNum | B1: Count | D1: ParNum | E1: Count | G1: ParNum | H1: Count
A2: Par1 | B2: =COUNTIF(Sheet1!$F$2:$AF$21,allcase!A2) -> 0 | D2: Par77 | E2: 10 | G2: Par77 | H2: 10
A3: Par2 | B3: =COUNTIF(Sheet1!$F$2:$AF$21,allcase!A3) -> 0 | D3: Par83 | E3: 10 | G3: Par83 | H3: 10
A4: Par3 | B4: =COUNTIF(Sheet1!$F$2:$AF$21,allcase!A4) -> 0 | D4: Par89 | E4: 10 | G4: Par89 | H4: 10
A5: Par4 | B5: =COUNTIF(Sheet1!$F$2:$AF$21,allcase!A5) -> 0 | D5: Par90 | E5: 10 | G5: Par90 | H5: 10
A6: Par5 | B6: =COUNTIF(Sheet1!$F$2:$AF$21,allcase!A6) -> 0 | D6: Par92 | E6: 10 | G6: Par92 | H6: 10
A7: Par6 | B7: =COUNTIF(Sheet1!$F$2:$AF$21,allcase!A7) -> 0 | D7: Par95 | E7: 10 | G7: Par95 | H7: 10
A8: Par7 | B8: =COUNTIF(Sheet1!$F$2:$AF$21,allcase!A8) -> 0 | D8: Par107 | E8: 10 | G8: Par107 | H8: 10
A9: Par8 | B9: =COUNTIF(Sheet1!$F$2:$AF$21,allcase!A9) -> 0 | D9: Par118 | E9: 10 | G9: Par118 | H9: 10
A10: Par9 | B10: =COUNTIF(Sheet1!$F$2:$AF$21,allcase!A10) -> 0 | D10: Par119 | E10: 10 | G10: Par119 | H10: 10
A11: Par10 | B11: =COUNTIF(Sheet1!$F$2:$AF$21,allcase!A11) -> 0 | D11: Par163 | E11: 10 | G11: Par163 | H11: 10
A12: Par11 | B12: =COUNTIF(Sheet1!$F$2:$AF$21,allcase!A12) -> 0 | D12: Par172 | E12: 10 | G12: Par172 | H12: 10
A13: Par12 | B13: =COUNTIF(Sheet1!$F$2:$AF$21,allcase!A13) -> 0 | D13: Par178 | E13: 10 | G13: Par178 | H13: 10
... A48: Par47 | B48: =COUNTIF(Sheet1!$F$2:$AF$21,allcase!A48) -> 1 | D48: Par214 | E48: 1 | G48: Par214 | H48: 1
A49: Par48 | B49: =COUNTIF(Sheet1!$F$2:$AF$21,allcase!A49) -> 0 | D49: Par1 | E49: 0
A50: Par49 | B50: =COUNTIF(Sheet1!$F$2:$AF$21,allcase!A50) -> 0 | D50: Par2 | E50: 0
A51: Par50 | B51: =COUNTIF(Sheet1!$F$2:$AF$21,allcase!A51) -> 0 | D51: Par3 | E51: 0
A52: Par51 | B52: =COUNTIF(Sheet1!$F$2:$AF$21,allcase!A52) -> 0 | D52: Par4 | E52: 0
A53: Par52 | B53: =COUNTIF(Sheet1!$F$2:$AF$21,allcase!A53) -> 0 | D53: Par5 | E53: 0
A54: Par53 | B54: =COUNTIF(Sheet1!$F$2:$AF$21,allcase!A54) -> 0 | D54: Par6 | E54: 0
A55: Par54 | B55: =COUNTIF(Sheet1!$F$2:$AF$21,allcase!A55) -> 0 | D55: Par7 | E55: 0
A56: Par55 | B56: =COUNTIF(Sheet1!$F$2:$AF$21,allcase!A56) -> 0 | D56: Par8 | E56: 0
A57: Par56 | B57: =COUNTIF(Sheet1!$F$2:$AF$21,allcase!A57) -> 0 | D57: Par9 | E57: 0
A58: Par57 | B58: =COUNTIF(Sheet1!$F$2:$AF$21,allcase!A58) -> 0 | D58: Par10 | E58: 0
A59: Par58 | B59: =COUNTIF(Sheet1!$F$2:$AF$21,allcase!A59) -> 0 | D59: Par11 | E59: 0
A60: Par59 | B60: =COUNTIF(Sheet1!$F$2:$AF$21,allcase!A60) -> 0 | D60: Par12 | E60: 0
... A237: Par236 | B237: =COUNTIF(Sheet1!$F$2:$AF$21,allcase!A237) -> 0 | D237: Par236 | E237: 0

Sheet max
A1: ParNum | B1: Count | D1: ParNum | E1: Count | G1: ParNum | H1: Count
A2: Par1 | B2: =COUNTIF(Sheet1!$F$22:$AF$41,allcase!A2) -> 0 | D2: Par77 | E2: 10 | G2: Par77 | H2: 10
A3: Par2 | B3: =COUNTIF(Sheet1!$F$22:$AF$41,allcase!A3) -> 0 | D3: Par92 | E3: 10 | G3: Par92 | H3: 10
A4: Par3 | B4: =COUNTIF(Sheet1!$F$22:$AF$41,allcase!A4) -> 0 | D4: Par95 | E4: 10 | G4: Par95 | H4: 10
A5: Par4 | B5: =COUNTIF(Sheet1!$F$22:$AF$41,allcase!A5) -> 0 | D5: Par119 | E5: 10 | G5: Par119 | H5: 10
A6: Par5 | B6: =COUNTIF(Sheet1!$F$22:$AF$41,allcase!A6) -> 0 | D6: Par172 | E6: 10 | G6: Par172 | H6: 10
A7: Par6 | B7: =COUNTIF(Sheet1!$F$22:$AF$41,allcase!A7) -> 0 | D7: Par178 | E7: 10 | G7: Par178 | H7: 10
A8: Par7 | B8: =COUNTIF(Sheet1!$F$22:$AF$41,allcase!A8) -> 0 | D8: Par181 | E8: 10 | G8: Par181 | H8: 10
A9: Par8 | B9: =COUNTIF(Sheet1!$F$22:$AF$41,allcase!A9) -> 0 | D9: Par187 | E9: 10 | G9: Par187 | H9: 10
A10: Par9 | B10: =COUNTIF(Sheet1!$F$22:$AF$41,allcase!A10) -> 0 | D10: Par193 | E10: 10 | G10: Par193 | H10: 10
A11: Par10 | B11: =COUNTIF(Sheet1!$F$22:$AF$41,allcase!A11) -> 0 | D11: Par219 | E11: 10 | G11: Par219 | H11: 10
A12: Par11 | B12: =COUNTIF(Sheet1!$F$22:$AF$41,allcase!A12) -> 0 | D12: Par220 | E12: 10 | G12: Par220 | H12: 10
A13: Par12 | B13: =COUNTIF(Sheet1!$F$22:$AF$41,allcase!A13) -> 0 | D13: Par221 | E13: 10 | G13: Par221 | H13: 10
... A47: Par46 | B47: =COUNTIF(Sheet1!$F$22:$AF$41,allcase!A47) -> 0 | D47: Par191 | E47: 1 | G47: Par191 | H47: 1
A48: Par47 | B48: =COUNTIF(Sheet1!$F$22:$AF$41,allcase!A48) -> 0 | D48: Par1 | E48: 0
A49: Par48 | B49: =COUNTIF(Sheet1!$F$22:$AF$41,allcase!A49) -> 0 | D49: Par2 | E49: 0
A50: Par49 | B50: =COUNTIF(Sheet1!$F$22:$AF$41,allcase!A50) -> 0 | D50: Par3 | E50: 0
A51: Par50 | B51: =COUNTIF(Sheet1!$F$22:$AF$41,allcase!A51) -> 0 | D51: Par4 | E51: 0
A52: Par51 | B52: =COUNTIF(Sheet1!$F$22:$AF$41,allcase!A52) -> 0 | D52: Par5 | E52: 0
A53: Par52 | B53: =COUNTIF(Sheet1!$F$22:$AF$41,allcase!A53) -> 0 | D53: Par6 | E53: 0
A54: Par53 | B54: =COUNTIF(Sheet1!$F$22:$AF$41,allcase!A54) -> 0 | D54: Par7 | E54: 0
A55: Par54 | B55: =COUNTIF(Sheet1!$F$22:$AF$41,allcase!A55) -> 0 | D55: Par8 | E55: 0
A56: Par55 | B56: =COUNTIF(Sheet1!$F$22:$AF$41,allcase!A56) -> 0 | D56: Par9 | E56: 0
A57: Par56 | B57: =COUNTIF(Sheet1!$F$22:$AF$41,allcase!A57) -> 0 | D57: Par10 | E57: 0
A58: Par57 | B58: =COUNTIF(Sheet1!$F$22:$AF$41,allcase!A58) -> 0 | D58: Par11 | E58: 0
A59: Par58 | B59: =COUNTIF(Sheet1!$F$22:$AF$41,allcase!A59) -> 0 | D59: Par12 | E59: 0
... A237: Par236 | B237: =COUNTIF(Sheet1!$F$22:$AF$41,allcase!A237) -> 0 | D237: Par236 | E237: 0

Sheet min
A1: ParNum | B1: Count | D1: ParNum | E1: Count | G1: ParNum | H1: Count
A2: Par1 | B2: =COUNTIF(Sheet1!$F$42:$AE$61,allcase!A2) -> 0 | D2: Par77 | E2: 10 | G2: Par77 | H2: 10
A3: Par2 | B3: =COUNTIF(Sheet1!$F$42:$AE$61,allcase!A3) -> 0 | D3: Par89 | E3: 10 | G3: Par89 | H3: 10
A4: Par3 | B4: =COUNTIF(Sheet1!$F$42:$AE$61,allcase!A4) -> 0 | D4: Par92 | E4: 10 | G4: Par92 | H4: 10
A5: Par4 | B5: =COUNTIF(Sheet1!$F$42:$AE$61,allcase!A5) -> 0 | D5: Par95 | E5: 10 | G5: Par95 | H5: 10
A6: Par5 | B6: =COUNTIF(Sheet1!$F$42:$AE$61,allcase!A6) -> 0 | D6: Par107 | E6: 10 | G6: Par107 | H6: 10
A7: Par6 | B7: =COUNTIF(Sheet1!$F$42:$AE$61,allcase!A7) -> 0 | D7: Par116 | E7: 10 | G7: Par116 | H7: 10
A8: Par7 | B8: =COUNTIF(Sheet1!$F$42:$AE$61,allcase!A8) -> 0 | D8: Par119 | E8: 10 | G8: Par119 | H8: 10
A9: Par8 | B9: =COUNTIF(Sheet1!$F$42:$AE$61,allcase!A9) -> 0 | D9: Par172 | E9: 10 | G9: Par172 | H9: 10
A10: Par9 | B10: =COUNTIF(Sheet1!$F$42:$AE$61,allcase!A10) -> 0 | D10: Par178 | E10: 10 | G10: Par178 | H10: 10
A11: Par10 | B11: =COUNTIF(Sheet1!$F$42:$AE$61,allcase!A11) -> 0 | D11: Par181 | E11: 10 | G11: Par181 | H11: 10
A12: Par11 | B12: =COUNTIF(Sheet1!$F$42:$AE$61,allcase!A12) -> 0 | D12: Par187 | E12: 10 | G12: Par187 | H12: 10
A13: Par12 | B13: =COUNTIF(Sheet1!$F$42:$AE$61,allcase!A13) -> 0 | D13: Par193 | E13: 10 | G13: Par193 | H13: 10
... A48: Par47 | B48: =COUNTIF(Sheet1!$F$42:$AE$61,allcase!A48) -> 1 | D48: Par213 | E48: 1 | G48: Par213 | H48: 1
A49: Par48 | B49: =COUNTIF(Sheet1!$F$42:$AE$61,allcase!A49) -> 0 | D49: Par1 | E49: 0
A50: Par49 | B50: =COUNTIF(Sheet1!$F$42:$AE$61,allcase!A50) -> 0 | D50: Par2 | E50: 0
A51: Par50 | B51: =COUNTIF(Sheet1!$F$42:$AE$61,allcase!A51) -> 0 | D51: Par3 | E51: 0
A52: Par51 | B52: =COUNTIF(Sheet1!$F$42:$AE$61,allcase!A52) -> 0 | D52: Par4 | E52: 0
A53: Par52 | B53: =COUNTIF(Sheet1!$F$42:$AE$61,allcase!A53) -> 0 | D53: Par5 | E53: 0
A54: Par53 | B54: =COUNTIF(Sheet1!$F$42:$AE$61,allcase!A54) -> 0 | D54: Par6 | E54: 0
A55: Par54 | B55: =COUNTIF(Sheet1!$F$42:$AE$61,allcase!A55) -> 0 | D55: Par7 | E55: 0
A56: Par55 | B56: =COUNTIF(Sheet1!$F$42:$AE$61,allcase!A56) -> 0 | D56: Par8 | E56: 0
A57: Par56 | B57: =COUNTIF(Sheet1!$F$42:$AE$61,allcase!A57) -> 0 | D57: Par9 | E57: 0
A58: Par57 | B58: =COUNTIF(Sheet1!$F$42:$AE$61,allcase!A58) -> 0 | D58: Par10 | E58: 0
A59: Par58 | B59: =COUNTIF(Sheet1!$F$42:$AE$61,allcase!A59) -> 0 | D59: Par11 | E59: 0
A60: Par59 | B60: =COUNTIF(Sheet1!$F$42:$AE$61,allcase!A60) -> 0 | D60: Par12 | E60: 0
... A237: Par236 | B237: =COUNTIF(Sheet1!$F$42:$AE$61,allcase!A237) -> 0 | D237: Par236 | E237: 0

Sheet Sheet6
A1: ParNum | B1: Count | D1: ParNum | E1: Count | G1: ParNum | H1: Count
A2: Par100 | B2: 1 | D2: Par102 | E2: 2 | G2: Par101 | H2: 5
A3: Par101 | B3: 1 | D3: Par106 | E3: 2 | G3: Par102 | H3: 2
A4: Par102 | B4: 5 | D4: Par107 | E4: 5 | G4: Par104 | H4: 5
A5: Par106 | B5: 7 | D5: Par112 | E5: 4 | G5: Par106 | H5: 5
A6: Par107 | B6: 10 | D6: Par113 | E6: 1 | G6: Par107 | H6: 10
A7: Par110 | B7: 2 | D7: Par114 | E7: 1 | G7: Par110 | H7: 5
A8: Par112 | B8: 6 | D8: Par116 | E8: 7 | G8: Par112 | H8: 1
A9: Par113 | B9: 7 | D9: Par118 | E9: 8 | G9: Par113 | H9: 9
A10: Par114 | B10: 3 | D10: Par119 | E10: 10 | G10: Par114 | H10: 2
A11: Par116 | B11: 7 | D11: Par157 | E11: 5 | G11: Par116 | H11: 10
A12: Par118 | B12: 10 | D12: Par160 | E12: 4 | G12: Par118 | H12: 6
A13: Par119 | B13: 10 | D13: Par163 | E13: 7 | G13: Par119 | H13: 10
... A47: Par94 | B47: 7 | D47: Par95 | E47: 10 | G47: Par95 | H47: 10
A48: Par95 | B48: 10 | G48: Par98 | H48: 4
